Workbook

Sheet 再审总览
A1: 甲醇金标准 100 项｜Google Drive 原始论文与 SI 复核
A2: 2026-10-12 · 10 篇主文 + 5 篇关键 SI · 原始“人工签署”栏未修改
A4: 类别 | B4: 数量（实时公式） | C4: 口径 | D4: 行动
A5: 直接印刷/单位等价 | B5: =COUNTIF('GoogleDrive原文逐项核验'!O$2:O$101,A5) -> 91 | C5: 原始表格/正文/图注直接给出数值；允许标准单位转换 | D5: 可按原文复核后签署
A6: 组成或比值推导 | B6: =COUNTIF('GoogleDrive原文逐项核验'!O$2:O$101,A6) -> 6 | C6: 数值由组成比或倒序比推得；并非该字段原样印刷 | D6: 保留计算式并标注 derived
A7: 原文值对但定位错误 | B7: =COUNTIF('GoogleDrive原文逐项核验'!O$2:O$101,A7) -> 1 | C7: 数值出现在正文，但不是原Excel声称的Table2 | D7: 修正定位
A8: 上界符号需恢复 | B8: =COUNTIF('GoogleDrive原文逐项核验'!O$2:O$101,A8) -> 1 | C8: 原文给的是小于号上界，不是等号实测值 | D8: 恢复 < 限定符
A9: 术语/计量口径需注明 | B9: =COUNTIF('GoogleDrive原文逐项核验'!O$2:O$101,A9) -> 1 | C9: 原论文列名Rate或Yield，而采集字段STY printed | D9: 保留原始单位及论文列名
A11: 总抽样数 | B11: =SUM(B5:B9) -> 100
A12: 数值差异 (非有争议的限定符) | B12: =COUNTIF('GoogleDrive原文逐项核验'!N$2:N$101,"MISMATCH") -> 0
A13: 本次恢复限定符的源记录 | B13: ID93（<0.1%，原文为上界）
A14: 未签署的人工金标准 | B14: 100/100 行（原表核对表N:R未改动）
A15: 冻结版候选成员复核 | B15: 100/100 条在冻结S5的310条有效比较候选中
A17: 审计声明 | B17: 本次是 AI 辅助原始论文审计，不构成独立人类审稿人的签署。非独立同分布抽样（先选10篇，每篇10值）；不能把简单二项Wilson区间直接当数据库总体准确率。
A19: 来源记录 | B19: 仅凭 Google Drive 已下载原始主文、SI 表和正文判定；未使用前一轮草稿作为正确性证据。
A20: 注意 | B20: Bansode 2013 SI使用MPa，且36 MPa不等于36 bar；这些压力只作为本次所抽样的行定位，不能据100项样本推断TheMeCat勘误已完全修好。Malik 2018正文7.6%与Table 6的7.7%原文内部不一致，此数值不在100个抽样字段中。

Sheet GoogleDrive原文逐项核验
A1: ID | B1: DOI | C1: 催化剂 | D1: 实验点 | E1: 核验字段 | F1: 原抽取值 | G1: 字段单位 | H1: 源CSV限定符 | I1: 抽取数值(比较用) | J1: 原文数字1 | K1: 原文数字2 | L1: 换算后原文值(公式) | M1: 差值(公式) | N1: 数值一致(公式) | O1: 证据类别 | P1: 印刷资格 | Q1: 原文实际表述/单位 | R1: 原文位置(PDF页) | S1: 精确表行/图注 | T1: 校正/保留事项 | U1: 原始PDF链接 | V1: 源文件SHA256 | W1: 来源标识
A2: 1 | B2: 10.1016/j.apcata.2018.04.036 | C2: 0.5Ca5P5ZC | D2: Fig 10a,b/text, 0.5Ca5P5ZC, 270 °C | E2: H2/CO2 | F2: 3 | G2: mol/mol | I2: 3 | J2: 3 | L2: =J2 -> 3 | M2: =I2-L2 -> 0 | N2: =IF(ABS(M2)<0.0000001,"MATCH","MISMATCH") -> MATCH | O2: 直接印刷/单位等价 | P2: Y: 原文表/正文/图注明确数字 | Q2: V(H2)/V(CO2)=3 | R2: PDF第10页 | S2: Fig. 10 caption, temperature series；Fig.10(a,b) common feed ratio, including 270°C point | T2: 原文数值及工况相符 | U2: https://drive.google.com/file/d/1--kU_GkfzNu3dB71N5o_RA6ri2lVgEcj/view | V2: 58e4e1e6d1ae981bc27217fd90ac31d34660d313ce095820052e13d7c065e1ab | W2: Malik-main
A3: 2 | B3: 10.1016/j.apcata.2018.04.036 | C3: 5P5ZC | D3: Table 6, 5P5ZC, 220 °C | E3: CO selectivity | F3: 0 | G3: % | H3: = | I3: 0 | J3: 0 | L3: =J3 -> 0 | M3: =I3-L3 -> 0 | N3: =IF(ABS(M3)<0.0000001,"MATCH","MISMATCH") -> MATCH | O3: 直接印刷/单位等价 | P3: Y: 原文表/正文/图注明确数字 | Q3: 5P5ZC: CO Sel. 0% | R3: PDF第8页 | S3: Table 6, 5P5ZC row, CO Sel.；Table 6 5P5ZC: X=6.3, SMeOH=100, SCO=0, SCH4=0 | T3: 原文数值及工况相符 | U3: https://drive.google.com/file/d/1--kU_GkfzNu3dB71N5o_RA6ri2lVgEcj/view | V3: 58e4e1e6d1ae981bc27217fd90ac31d34660d313ce095820052e13d7c065e1ab | W3: Malik-main
A4: 3 | B4: 10.1016/j.apcata.2018.04.036 | C4: 5P5ZC | D4: Table 6, 5P5ZC, 220 °C | E4: pressure | F4: 30 | G4: bar | I4: 30 | J4: 30 | L4: =J4 -> 30 | M4: =I4-L4 -> 0 | N4: =IF(ABS(M4)<0.0000001,"MATCH","MISMATCH") -> MATCH | O4: 直接印刷/单位等价 | P4: Y: 原文表/正文/图注明确数字 | Q4: P=30 bar | R4: PDF第8页 | S4: Table 6 reaction conditions；Table 6 shared pressure | T4: 原文数值及工况相符 | U4: https://drive.google.com/file/d/1--kU_GkfzNu3dB71N5o_RA6ri2lVgEcj/view | V4: 58e4e1e6d1ae981bc27217fd90ac31d34660d313ce095820052e13d7c065e1ab | W4: Malik-main
A5: 4 | B5: 10.1016/j.apcata.2018.04.036 | C5: 5PC | D5: Table 6, 5PC, 220 °C | E5: CH3OH selectivity | F5: 70.1 | G5: % | H5: = | I5: 70.1 | J5: 70.1 | L5: =J5 -> 70.1 | M5: =I5-L5 -> 0 | N5: =IF(ABS(M5)<0.0000001,"MATCH","MISMATCH") -> MATCH | O5: 直接印刷/单位等价 | P5: Y: 原文表/正文/图注明确数字 | Q5: 5PC: CH3OH Sel. 70.1% | R5: PDF第8页 | S5: Table 6, 5PC row；5PC X=1.7, SMeOH=70.1, SCO=27.6, SCH4=2.3 | T5: 原文数值及工况相符 | U5: https://drive.google.com/file/d/1--kU_GkfzNu3dB71N5o_RA6ri2lVgEcj/view | V5: 58e4e1e6d1ae981bc27217fd90ac31d34660d313ce095820052e13d7c065e1ab | W5: Malik-main
A6: 5 | B6: 10.1016/j.apcata.2018.04.036 | C6: 0.5Ca5P5ZC | D6: Table 6, 0.5Ca5P5ZC, 220 °C | E6: CH4 selectivity | F6: 0 | G6: % | H6: = | I6: 0 | J6: 0 | L6: =J6 -> 0 | M6: =I6-L6 -> 0 | N6: =IF(ABS(M6)<0.0000001,"MATCH","MISMATCH") -> MATCH | O6: 直接印刷/单位等价 | P6: Y: 原文表/正文/图注明确数字 | Q6: 0.5Ca5P5ZC: CH4 Sel. 0% | R6: PDF第8页 | S6: Table 6, 0.5Ca5P5ZC row；0.5Ca5P5ZC X=7.7, SMeOH=100, SCO=0, SCH4=0 | T6: 原文数值及工况相符 | U6: https://drive.google.com/file/d/1--kU_GkfzNu3dB71N5o_RA6ri2lVgEcj/view | V6: 58e4e1e6d1ae981bc27217fd90ac31d34660d313ce095820052e13d7c065e1ab | W6: Malik-main
A7: 6 | B7: 10.1016/j.apcata.2018.04.036 | C7: 5PC | D7: Table 6, 5PC, 220 °C | E7: H2/CO2 | F7: 3 | G7: mol/mol | I7: 3 | J7: 3 | L7: =J7 -> 3 | M7: =I7-L7 -> 0 | N7: =IF(ABS(M7)<0.0000001,"MATCH","MISMATCH") -> MATCH | O7: 直接印刷/单位等价 | P7: Y: 原文表/正文/图注明确数字 | Q7: V(H2)/V(CO2)=3 | R7: PDF第8页 | S7: Table 6 reaction conditions；Shared feed applies to 5PC row | T7: 原文数值及工况相符 | U7: https://drive.google.com/file/d/1--kU_GkfzNu3dB71N5o_RA6ri2lVgEcj/view | V7: 58e4e1e6d1ae981bc27217fd90ac31d34660d313ce095820052e13d7c065e1ab | W7: Malik-main
A8: 7 | B8: 10.1016/j.apcata.2018.04.036 | C8: 5PC | D8: Table 6, 5PC, 220 °C | E8: CH4 selectivity | F8: 2.3 | G8: % | H8: = | I8: 2.3 | J8: 2.3 | L8: =J8 -> 2.3 | M8: =I8-L8 -> 0 | N8: =IF(ABS(M8)<0.0000001,"MATCH","MISMATCH") -> MATCH | O8: 直接印刷/单位等价 | P8: Y: 原文表/正文/图注明确数字 | Q8: 5PC: CH4 Sel. 2.3% | R8: PDF第8页 | S8: Table 6, 5PC row；5PC X=1.7, SMeOH=70.1, SCO=27.6, SCH4=2.3 | T8: 原文数值及工况相符 | U8: https://drive.google.com/file/d/1--kU_GkfzNu3dB71N5o_RA6ri2lVgEcj/view | V8: 58e4e1e6d1ae981bc27217fd90ac31d34660d313ce095820052e13d7c065e1ab | W8: Malik-main
A9: 8 | B9: 10.1016/j.apcata.2018.04.036 | C9: 5PC | D9: Table 6, 5PC, 220 °C | E9: CO2 conversion | F9: 1.7 | G9: % | H9: = | I9: 1.7 | J9: 1.7 | L9: =J9 -> 1.7 | M9: =I9-L9 -> 0 | N9: =IF(ABS(M9)<0.0000001,"MATCH","MISMATCH") -> MATCH | O9: 直接印刷/单位等价 | P9: Y: 原文表/正文/图注明确数字 | Q9: 5PC: CO2 Conv. 1.7% | R9: PDF第8页 | S9: Table 6, 5PC row；5PC X=1.7, SMeOH=70.1, SCO=27.6, SCH4=2.3 | T9: 原文数值及工况相符 | U9: https://drive.google.com/file/d/1--kU_GkfzNu3dB71N5o_RA6ri2lVgEcj/view | V9: 58e4e1e6d1ae981bc27217fd90ac31d34660d313ce095820052e13d7c065e1ab | W9: Malik-main
A10: 9 | B10: 10.1016/j.apcata.2018.04.036 | C10: 5P5ZC | D10: Table 6, 5P5ZC, 220 °C | E10: H2/CO2 | F10: 3 | G10: mol/mol | I10: 3 | J10: 3 | L10: =J10 -> 3 | M10: =I10-L10 -> 0 | N10: =IF(ABS(M10)<0.0000001,"MATCH","MISMATCH") -> MATCH | O10: 直接印刷/单位等价 | P10: Y: 原文表/正文/图注明确数字 | Q10: V(H2)/V(CO2)=3 | R10: PDF第8页 | S10: Table 6 reaction conditions；Shared feed applies to 5P5ZC | T10: 原文数值及工况相符 | U10: https://drive.google.com/file/d/1--kU_GkfzNu3dB71N5o_RA6ri2lVgEcj/view | V10: 58e4e1e6d1ae981bc27217fd90ac31d34660d313ce095820052e13d7c065e1ab | W10: Malik-main
A11: 10 | B11: 10.1016/j.apcata.2018.04.036 | C11: 0.5Ca5P5ZC | D11: Table 6, 0.5Ca5P5ZC, 220 °C | E11: CO selectivity | F11: 0 | G11: % | H11: = | I11: 0 | J11: 0 | L11: =J11 -> 0 | M11: =I11-L11 -> 0 | N11: =IF(ABS(M11)<0.0000001,"MATCH","MISMATCH") -> MATCH | O11: 直接印刷/单位等价 | P11: Y: 原文表/正文/图注明确数字 | Q11: 0.5Ca5P5ZC: CO Sel. 0% | R11: PDF第8页 | S11: Table 6, 0.5Ca5P5ZC row；0.5Ca5P5ZC X=7.7, SMeOH=100, SCO=0, SCH4=0 | T11: 原文数值及工况相符 | U11: https://drive.google.com/file/d/1--kU_GkfzNu3dB71N5o_RA6ri2lVgEcj/view | V11: 58e4e1e6d1ae981bc27217fd90ac31d34660d313ce095820052e13d7c065e1ab | W11: Malik-main
A12: 11 | B12: 10.1126/sciadv.abi6012 | C12: a-ZrO2 | D12: SI Table S2 row a-ZrO2 | E12: CO selectivity | F12: 26.8 | G12: % | H12: = | I12: 26.8 | J12: 26.8 | L12: =J12 -> 26.8 | M12: =I12-L12 -> 0 | N12: =IF(ABS(M12)<0.0000001,"MATCH","MISMATCH") -> MATCH | O12: 直接印刷/单位等价 | P12: Y: 原文表/正文/图注明确数字 | Q12: a-ZrO2: CO selectivity 26.8% | R12: PDF第19页 | S12: Table S2, a-ZrO2 row, CO | T12: 原文数值及工况相符 | U12: https://drive.google.com/file/d/1w4nbo1f-SQjZ1_mP63Uc7HuFbekYMUyA/view | V12: ebff6b65cec05a24ea067333c5cb805b9dcc83408f1205ac2781c578bde9b866 | W12: Meng-SI
A13: 12 | B13: 10.1126/sciadv.abi6012 | C13: InNi3C0.5/t-ZrO2 | D13: Fig. 2B, InNi3C0.5/t-ZrO2, 24000 ml gcat-1 hour-1 | E13: STY (printed) | F13: 0.3 gMeOH gcat−1 hour−1 | G13: as printed | H13: = | I13: 0.3 | J13: 0.3 | L13: =J13 -> 0.3 | M13: =I13-L13 -> 0 | N13: =IF(ABS(M13)<0.0000001,"MATCH","MISMATCH") -> MATCH | O13: 直接印刷/单位等价 | P13: Y: 原文表/正文/图注明确数字 | Q13: 0.30 gMeOH gcat^-1 h^-1 | R13: PDF第20页 | S13: Table S3, InNi3C0.5/t-ZrO2 row, STY；Table S3 300°C/4MPa/GHSV=24000 | T13: 原文数值及工况相符 | U13: https://drive.google.com/file/d/1w4nbo1f-SQjZ1_mP63Uc7HuFbekYMUyA/view | V13: ebff6b65cec05a24ea067333c5cb805b9dcc83408f1205ac2781c578bde9b866 | W13: Meng-SI
A14: 13 | B14: 10.1126/sciadv.abi6012 | C14: SiO2 | D14: SI Table S2 row SiO2 | E14: H2/CO2 | F14: 3 | G14: mol/mol | I14: 3 | J14: 3 | L14: =J14 -> 3 | M14: =I14-L14 -> 0 | N14: =IF(ABS(M14)<0.0000001,"MATCH","MISMATCH") -> MATCH | O14: 直接印刷/单位等价 | P14: Y: 原文表/正文/图注明确数字 | Q14: H2/CO2=3/1 | R14: PDF第19页 | S14: Table S2, footnote reaction conditions；Same conditions for SiO2 row | T14: 原文数值及工况相符 | U14: https://drive.google.com/file/d/1w4nbo1f-SQjZ1_mP63Uc7HuFbekYMUyA/view | V14: ebff6b65cec05a24ea067333c5cb805b9dcc83408f1205ac2781c578bde9b866 | W14: Meng-SI
A15: 14 | B15: 10.1126/sciadv.abi6012 | C15: InNi3C0.5/ZnO | D15: SI Table S2 row InNi3C0.5/ZnO | E15: CO2 conversion | F15: 7.8 | G15: % | H15: = | I15: 7.8 | J15: 7.8 | L15: =J15 -> 7.8 | M15: =I15-L15 -> 0 | N15: =IF(ABS(M15)<0.0000001,"MATCH","MISMATCH") -> MATCH | O15: 直接印刷/单位等价 | P15: Y: 原文表/正文/图注明确数字 | Q15: InNi3C0.5/ZnO: CO2 Conv. 7.8% | R15: PDF第19页 | S15: Table S2, InNi3C0.5/ZnO row | T15: 原文数值及工况相符 | U15: https://drive.google.com/file/d/1w4nbo1f-SQjZ1_mP63Uc7HuFbekYMUyA/view | V15: ebff6b65cec05a24ea067333c5cb805b9dcc83408f1205ac2781c578bde9b866 | W15: Meng-SI
A16: 15 | B16: 10.1126/sciadv.abi6012 | C16: InNi3C0.5/TiO2 | D16: SI Table S2 row InNi3C0.5/TiO2 | E16: CH3OH selectivity | F16: 66.3 | G16: % | H16: = | I16: 66.3 | J16: 66.3 | L16: =J16 -> 66.3 | M16: =I16-L16 -> 0 | N16: =IF(ABS(M16)<0.0000001,"MATCH","MISMATCH") -> MATCH | O16: 直接印刷/单位等价 | P16: Y: 原文表/正文/图注明确数字 | Q16: InNi3C0.5/TiO2: CH3OH Sel. 66.3% | R16: PDF第19页 | S16: Table S2, InNi3C0.5/TiO2 row | T16: 原文数值及工况相符 | U16: https://drive.google.com/file/d/1w4nbo1f-SQjZ1_mP63Uc7HuFbekYMUyA/view | V16: ebff6b65cec05a24ea067333c5cb805b9dcc83408f1205ac2781c578bde9b866 | W16: Meng-SI
A17: 16 | B17: 10.1126/sciadv.abi6012 | C17: m-ZrO2 | D17: SI Table S2 row m-ZrO2 | E17: space velocity | F17: 12000 mL gcat−1 h−1 | G17: as printed | I17: 12000 | J17: 12000 | L17: =J17 -> 12000 | M17: =I17-L17 -> 0 | N17: =IF(ABS(M17)<0.0000001,"MATCH","MISMATCH") -> MATCH | O17: 直接印刷/单位等价 | P17: Y: 原文表/正文/图注明确数字 | Q17: GHSV 12,000 mL gcat^-1 h^-1 | R17: PDF第19页 | S17: Table S2, footnote reaction conditions | T17: 原文数值及工况相符 | U17: https://drive.google.com/file/d/1w4nbo1f-SQjZ1_mP63Uc7HuFbekYMUyA/view | V17: ebff6b65cec05a24ea067333c5cb805b9dcc83408f1205ac2781c578bde9b866 | W17: Meng-SI
A18: 17 | B18: 10.1126/sciadv.abi6012 | C18: InNi3C0.5/a-ZrO2 | D18: Fig. 2A, InNi3C0.5/a-ZrO2, 12000 ml gcat-1 hour-1 | E18: CH4 selectivity | F18: 0.4 | G18: % | H18: = | I18: 0.4 | J18: 0.4 | L18: =J18 -> 0.4 | M18: =I18-L18 -> 0 | N18: =IF(ABS(M18)<0.0000001,"MATCH","MISMATCH") -> MATCH | O18: 直接印刷/单位等价 | P18: Y: 原文表/正文/图注明确数字 | Q18: InNi3C0.5/a-ZrO2: CH4 Sel. 0.4% | R18: PDF第19页 | S18: Table S2, InNi3C0.5/a-ZrO2 row；Exact numeric printed in SI Table S2, not only Fig.2A graph | T18: 原文数值及工况相符 | U18: https://drive.google.com/file/d/1w4nbo1f-SQjZ1_mP63Uc7HuFbekYMUyA/view | V18: ebff6b65cec05a24ea067333c5cb805b9dcc83408f1205ac2781c578bde9b866 | W18: Meng-SI
A19: 18 | B19: 10.1126/sciadv.abi6012 | C19: InNi3C0.5/m-ZrO2 | D19: Fig. 2A, InNi3C0.5/m-ZrO2, 12000 ml gcat-1 hour-1 | E19: H2/CO2 | F19: 3 | G19: mol/mol | I19: 3 | J19: 3 | L19: =J19 -> 3 | M19: =I19-L19 -> 0 | N19: =IF(ABS(M19)<0.0000001,"MATCH","MISMATCH") -> MATCH | O19: 直接印刷/单位等价 | P19: Y: 原文表/正文/图注明确数字 | Q19: H2/CO2=3/1 | R19: PDF第19页 | S19: Table S2, footnote reaction conditions；Also Fig.2A caption | T19: 原文数值及工况相符 | U19: https://drive.google.com/file/d/1w4nbo1f-SQjZ1_mP63Uc7HuFbekYMUyA/view | V19: ebff6b65cec05a24ea067333c5cb805b9dcc83408f1205ac2781c578bde9b866 | W19: Meng-SI
A20: 19 | B20: 10.1126/sciadv.abi6012 | C20: m-ZrO2 | D20: SI Table S2 row m-ZrO2 | E20: temperature | F20: 300 | G20: °C (from K) | I20: 300 | J20: 300 | L20: =J20 -> 300 | M20: =I20-L20 -> 0 | N20: =IF(ABS(M20)<0.0000001,"MATCH","MISMATCH") -> MATCH | O20: 直接印刷/单位等价 | P20: Y: 原文表/正文/图注明确数字 | Q20: T=300°C | R20: PDF第19页 | S20: Table S2, footnote reaction conditions；Direct 300°C print in SI, despite workbook unit label from K | T20: 原文数值及工况相符 | U20: https://drive.google.com/file/d/1w4nbo1f-SQjZ1_mP63Uc7HuFbekYMUyA/view | V20: ebff6b65cec05a24ea067333c5cb805b9dcc83408f1205ac2781c578bde9b866 | W20: Meng-SI
A21: 20 | B21: 10.1126/sciadv.abi6012 | C21: InNi3C0.5/Fe3O4 | D21: Text/Table S7, InNi3C0.5/Fe3O4, 325C, 4.0 MPa, H2/CO2 8:1, GHSV 30000 | E21: pressure | F21: 40 | G21: bar | I21: 40 | J21: 4 | L21: =J21*10 -> 40 | M21: =I21-L21 -> 0 | N21: =IF(ABS(M21)<0.0000001,"MATCH","MISMATCH") -> MATCH | O21: 直接印刷/单位等价 | P21: Y: 原文数字直印；已换算单位 | Q21: P=4.0 MPa | R21: PDF第25页 | S21: Table S7, InNi3C0.5/Fe3O4, 325°C, P=4MPa, ratio 8/1；Two P4MPa ratio=8 rows exist at different GHSV; pressure is unchanged | T21: 原文数值及工况相符 | U21: https://drive.google.com/file/d/1w4nbo1f-SQjZ1_mP63Uc7HuFbekYMUyA/view | V21: ebff6b65cec05a24ea067333c5cb805b9dcc83408f1205ac2781c578bde9b866 | W21: Meng-SI
A22: 21 | B22: 10.1039/c2cy20604h | C22: Cu–Ba/Al2O3 | D22: Text, Cu-Ba/Al2O3, 443 K, 36 MPa | E22: temperature | F22: 169.85 | G22: °C (from K) | I22: 169.85 | J22: 443 | L22: =ROUND(J22-273.15,2) -> 169.85 | M22: =I22-L22 -> 0 | N22: =IF(ABS(M22)<0.0000001,"MATCH","MISMATCH") -> MATCH | O22: 直接印刷/单位等价 | P22: Y: 原文数字直印；已换算单位 | Q22: 443 K | R22: PDF第4页 | S22: Table 3 (= S3), Cu-Ba, 443K / 36MPa | T22: 原文数值及工况相符 | U22: https://drive.google.com/file/d/1vAP6iNS7sXYNV2z9__QqhMEJt5o0Rllo/view | V22: 9a45c3d5c0555001a60b3b6485b3a9799500a57079fc266f8cdf0562ad5ebcf0 | W22: Bansode-SI
A23: 22 | B23: 10.1039/c2cy20604h | C23: Cu–Ba/Al2O3 | D23: SI Table 3, 503 K, 36 MPa | E23: STY (printed) | F23: 56.5 mg gcat-1 h-1 | G23: as printed | H23: = | I23: 56.5 | J23: 56.5 | L23: =J23 -> 56.5 | M23: =I23-L23 -> 0 | N23: =IF(ABS(M23)<0.0000001,"MATCH","MISMATCH") -> MATCH | O23: 直接印刷/单位等价 | P23: Y: 原文表/正文/图注明确数字 | Q23: 56.5 mg gcat^-1 h^-1 | R23: PDF第4页 | S23: Table 3 (= S3), Cu-Ba, 503K / 36MPa, CH3OH yield；This is printed yield, not a percent selectivity | T23: 原文数值及工况相符 | U23: https://drive.google.com/file/d/1vAP6iNS7sXYNV2z9__QqhMEJt5o0Rllo/view | V23: 9a45c3d5c0555001a60b3b6485b3a9799500a57079fc266f8cdf0562ad5ebcf0 | W23: Bansode-SI
A24: 23 | B24: 10.1039/c2cy20604h | C24: Cu–Ba/Al2O3 | D24: SI Table 3, 533 K, 0.4 MPa | E24: CH3OH selectivity | F24: 4.4 | G24: % | H24: = | I24: 4.4 | J24: 4.4 | L24: =J24 -> 4.4 | M24: =I24-L24 -> 0 | N24: =IF(ABS(M24)<0.0000001,"MATCH","MISMATCH") -> MATCH | O24: 直接印刷/单位等价 | P24: Y: 原文表/正文/图注明确数字 | Q24: 4.4% | R24: PDF第4页 | S24: Table 3 (= S3), Cu-Ba, 533K / 0.4MPa, CH3OH Sel. | T24: 原文数值及工况相符 | U24: https://drive.google.com/file/d/1vAP6iNS7sXYNV2z9__QqhMEJt5o0Rllo/view | V24: 9a45c3d5c0555001a60b3b6485b3a9799500a57079fc266f8cdf0562ad5ebcf0 | W24: Bansode-SI
A25: 24 | B25: 10.1039/c2cy20604h | C25: Cu/Al2O3 | D25: Fig 5/Fig 6, Cu/Al2O3, 443 K, 10 MPa | E25: CH3OH selectivity | F25: 80 | G25: % | H25: = | I25: 80 | J25: 80 | L25: =J25 -> 80 | M25: =I25-L25 -> 0 | N25: =IF(ABS(M25)<0.0000001,"MATCH","MISMATCH") -> MATCH | O25: 直接印刷/单位等价 | P25: Y: 原文表/正文/图注明确数字 | Q25: 80.0% | R25: PDF第2页 | S25: Table S1, Cu/Al2O3, 443K / 10MPa, CH3OH Sel. | T25: 原文数值及工况相符 | U25: https://drive.google.com/file/d/1vAP6iNS7sXYNV2z9__QqhMEJt5o0Rllo/view | V25: 9a45c3d5c0555001a60b3b6485b3a9799500a57079fc266f8cdf0562ad5ebcf0 | W25: Bansode-SI
A26: 25 | B26: 10.1039/c2cy20604h | C26: Cu–K/Al2O3 | D26: Fig 7, Cu-K/Al2O3, 533 K, 36 MPa | E26: STY (printed) | F26: 10.6 mg gcat-1 h-1 | G26: as printed | H26: = | I26: 10.6 | J26: 10.6 | L26: =J26 -> 10.6 | M26: =I26-L26 -> 0 | N26: =IF(ABS(M26)<0.0000001,"MATCH","MISMATCH") -> MATCH | O26: 直接印刷/单位等价 | P26: Y: 原文表/正文/图注明确数字 | Q26: 10.6 mg gcat^-1 h^-1 | R26: PDF第3页 | S26: Table S2, Cu-K, 533K / 36MPa, CH3OH yield | T26: 原文数值及工况相符 | U26: https://drive.google.com/file/d/1vAP6iNS7sXYNV2z9__QqhMEJt5o0Rllo/view | V26: 9a45c3d5c0555001a60b3b6485b3a9799500a57079fc266f8cdf0562ad5ebcf0 | W26: Bansode-SI
A27: 26 | B27: 10.1039/c2cy20604h | C27: Cu–Ba/Al2O3 | D27: SI Table 3, 553 K, 0.4 MPa | E27: CO selectivity | F27: 98.1 | G27: % | H27: = | I27: 98.1 | J27: 98.1 | L27: =J27 -> 98.1 | M27: =I27-L27 -> 0 | N27: =IF(ABS(M27)<0.0000001,"MATCH","MISMATCH") -> MATCH | O27: 直接印刷/单位等价 | P27: Y: 原文表/正文/图注明确数字 | Q27: 98.1% | R27: PDF第4页 | S27: Table 3 (= S3), Cu-Ba, 553K / 0.4MPa, CO Sel. | T27: 原文数值及工况相符 | U27: https://drive.google.com/file/d/1vAP6iNS7sXYNV2z9__QqhMEJt5o0Rllo/view | V27: 9a45c3d5c0555001a60b3b6485b3a9799500a57079fc266f8cdf0562ad5ebcf0 | W27: Bansode-SI
A28: 27 | B28: 10.1039/c2cy20604h | C28: Cu–Ba/Al2O3 | D28: SI Table 3, 443 K, 0.4 MPa | E28: CO selectivity | F28: 72.5 | G28: % | H28: = | I28: 72.5 | J28: 72.5 | L28: =J28 -> 72.5 | M28: =I28-L28 -> 0 | N28: =IF(ABS(M28)<0.0000001,"MATCH","MISMATCH") -> MATCH | O28: 直接印刷/单位等价 | P28: Y: 原文表/正文/图注明确数字 | Q28: 72.5% | R28: PDF第4页 | S28: Table 3 (= S3), Cu-Ba, 443K / 0.4MPa, CO Sel. | T28: 原文数值及工况相符 | U28: https://drive.google.com/file/d/1vAP6iNS7sXYNV2z9__QqhMEJt5o0Rllo/view | V28: 9a45c3d5c0555001a60b3b6485b3a9799500a57079fc266f8cdf0562ad5ebcf0 | W28: Bansode-SI
A29: 28 | B29: 10.1039/c2cy20604h | C29: Cu–Ba/Al2O3 | D29: Fig 8, Cu-Ba/Al2O3, 473 K, 10 MPa | E29: temperature | F29: 199.85 | G29: °C (from K) | I29: 199.85 | J29: 473 | L29: =ROUND(J29-273.15,2) -> 199.85 | M29: =I29-L29 -> 0 | N29: =IF(ABS(M29)<0.0000001,"MATCH","MISMATCH") -> MATCH | O29: 直接印刷/单位等价 | P29: Y: 原文数字直印；已换算单位 | Q29: 473 K | R29: PDF第4页 | S29: Table 3 (= S3), Cu-Ba, 473K / 10MPa | T29: 原文数值及工况相符 | U29: https://drive.google.com/file/d/1vAP6iNS7sXYNV2z9__QqhMEJt5o0Rllo/view | V29: 9a45c3d5c0555001a60b3b6485b3a9799500a57079fc266f8cdf0562ad5ebcf0 | W29: Bansode-SI
A30: 29 | B30: 10.1039/c2cy20604h | C30: Cu–K/Al2O3 | D30: Fig 7/Fig 8, Cu-K/Al2O3, 473 K, 36 MPa | E30: CO2 conversion | F30: 8.9 | G30: % | H30: = | I30: 8.9 | J30: 8.9 | L30: =J30 -> 8.9 | M30: =I30-L30 -> 0 | N30: =IF(ABS(M30)<0.0000001,"MATCH","MISMATCH") -> MATCH | O30: 直接印刷/单位等价 | P30: Y: 原文表/正文/图注明确数字 | Q30: 8.9% | R30: PDF第3页 | S30: Table S2, Cu-K, 473K / 36MPa, CO2 conversion | T30: 原文数值及工况相符 | U30: https://drive.google.com/file/d/1vAP6iNS7sXYNV2z9__QqhMEJt5o0Rllo/view | V30: 9a45c3d5c0555001a60b3b6485b3a9799500a57079fc266f8cdf0562ad5ebcf0 | W30: Bansode-SI
A31: 30 | B31: 10.1039/c2cy20604h | C31: Cu–K/Al2O3 | D31: Fig 7, Cu-K/Al2O3, 533 K, 3 MPa | E31: CO selectivity | F31: 98.1 | G31: % | H31: = | I31: 98.1 | J31: 98.1 | L31: =J31 -> 98.1 | M31: =I31-L31 -> 0 | N31: =IF(ABS(M31)<0.0000001,"MATCH","MISMATCH") -> MATCH | O31: 直接印刷/单位等价 | P31: Y: 原文表/正文/图注明确数字 | Q31: 98.1% | R31: PDF第3页 | S31: Table S2, Cu-K, 533K / 3MPa, CO Sel. | T31: 原文数值及工况相符 | U31: https://drive.google.com/file/d/1vAP6iNS7sXYNV2z9__QqhMEJt5o0Rllo/view | V31: 9a45c3d5c0555001a60b3b6485b3a9799500a57079fc266f8cdf0562ad5ebcf0 | W31: Bansode-SI
A32: 31 | B32: 10.1038/s41467-019-11349-9 | C32: Pd–In2O3 CP | D32: Table 2 Pd–In2O3 CP, WHSV 48,000 initial | E32: pressure | F32: 50 | G32: bar | I32: 50 | J32: 5 | L32: =J32*10 -> 50 | M32: =I32-L32 -> 0 | N32: =IF(ABS(M32)<0.0000001,"MATCH","MISMATCH") -> MATCH | O32: 直接印刷/单位等价 | P32: Y: 原文数字直印；已换算单位 | Q32: 5 MPa | R32: PDF第9页 | S32: Table 2, Pd-In2O3 CP row, P | T32: 原文数值及工况相符 | U32: https://drive.google.com/file/d/1SpUJIHvYqa2nrDV6DeXCxRVpO02YyOJ1/view | V32: ee86dd4c833be2702f5e825c66a6dd3b1cc8c609bd9cc441ee955a26b3cd5330 | W32: Frei-main
A33: 32 | B33: 10.1038/s41467-019-11349-9 | C33: CP | D33: Fig. 6/text Pd–In2O3 CP stability, start | E33: CH3OH selectivity | F33: 75 | G33: % | H33: = | I33: 75 | J33: 75 | L33: =J33 -> 75 | M33: =I33-L33 -> 0 | N33: =IF(ABS(M33)<0.0000001,"MATCH","MISMATCH") -> MATCH | O33: 直接印刷/单位等价 | P33: Y: 原文表/正文/图注明确数字 | Q33: selectivity from 75% to 78% | R33: PDF第8页 | S33: Fig.6 stability paragraph, selectivity start | T33: Table2另报78%（不同测量口径）；必须保留Fig6起点上下文 | U33: https://drive.google.com/file/d/1SpUJIHvYqa2nrDV6DeXCxRVpO02YyOJ1/view | V33: ee86dd4c833be2702f5e825c66a6dd3b1cc8c609bd9cc441ee955a26b3cd5330 | W33: Frei-main
A34: 33 | B34: 10.1038/s41467-019-11349-9 | C34: Pd–In2O3 CP | D34: Table 2 Pd–In2O3 CP, WHSV 48,000 initial | E34: temperature | F34: 279.85 | G34: °C (from K) | I34: 279.85 | J34: 553 | L34: =ROUND(J34-273.15,2) -> 279.85 | M34: =I34-L34 -> 0 | N34: =IF(ABS(M34)<0.0000001,"MATCH","MISMATCH") -> MATCH | O34: 直接印刷/单位等价 | P34: Y: 原文数字直印；已换算单位 | Q34: 553 K | R34: PDF第9页 | S34: Table 2, Pd-In2O3 CP, T | T34: 原文数值及工况相符 | U34: https://drive.google.com/file/d/1SpUJIHvYqa2nrDV6DeXCxRVpO02YyOJ1/view | V34: ee86dd4c833be2702f5e825c66a6dd3b1cc8c609bd9cc441ee955a26b3cd5330 | W34: Frei-main
A35: 34 | B35: 10.1038/s41467-019-11349-9 | C35: CP | D35: Fig. 6/text Pd–In2O3 CP stability, after 500 h | E35: temperature | F35: 279.85 | G35: °C (from K) | I35: 279.85 | J35: 553 | L35: =ROUND(J35-273.15,2) -> 279.85 | M35: =I35-L35 -> 0 | N35: =IF(ABS(M35)<0.0000001,"MATCH","MISMATCH") -> MATCH | O35: 直接印刷/单位等价 | P35: Y: 原文数字直印；已换算单位 | Q35: T=553 K | R35: PDF第8页 | S35: Fig.6 500h stability caption, T | T35: 原文数值及工况相符 | U35: https://drive.google.com/file/d/1SpUJIHvYqa2nrDV6DeXCxRVpO02YyOJ1/view | V35: ee86dd4c833be2702f5e825c66a6dd3b1cc8c609bd9cc441ee955a26b3cd5330 | W35: Frei-main
A36: 35 | B36: 10.1038/s41467-019-11349-9 | C36: CP | D36: Fig. 6/text Pd–In2O3 CP stability, start | E36: CO2 conversion | F36: 9.7 | G36: % | H36: = | I36: 9.7 | J36: 9.7 | L36: =J36 -> 9.7 | M36: =I36-L36 -> 0 | N36: =IF(ABS(M36)<0.0000001,"MATCH","MISMATCH") -> MATCH | O36: 直接印刷/单位等价 | P36: Y: 原文表/正文/图注明确数字 | Q36: CO2 conversion from 9.7% to 9.2% | R36: PDF第8页 | S36: Fig.6 stability text CO2 conversion start | T36: 原文数值及工况相符 | U36: https://drive.google.com/file/d/1SpUJIHvYqa2nrDV6DeXCxRVpO02YyOJ1/view | V36: ee86dd4c833be2702f5e825c66a6dd3b1cc8c609bd9cc441ee955a26b3cd5330 | W36: Frei-main
A37: 36 | B37: 10.1038/s41467-019-11349-9 | C37: CP | D37: Fig. 6/text Pd–In2O3 CP stability, start | E37: H2/CO2 | F37: 4 | G37: mol/mol | I37: 4 | J37: 4 | L37: =J37 -> 4 | M37: =I37-L37 -> 0 | N37: =IF(ABS(M37)<0.0000001,"MATCH","MISMATCH") -> MATCH | O37: 直接印刷/单位等价 | P37: Y: 原文表/正文/图注明确数字 | Q37: H2/CO2=4 | R37: PDF第8页 | S37: Fig.6 stability caption H2/CO2 | T37: 原文数值及工况相符 | U37: https://drive.google.com/file/d/1SpUJIHvYqa2nrDV6DeXCxRVpO02YyOJ1/view | V37: ee86dd4c833be2702f5e825c66a6dd3b1cc8c609bd9cc441ee955a26b3cd5330 | W37: Frei-main
A38: 37 | B38: 10.1038/s41467-019-11349-9 | C38: CP | D38: Fig. 6/text Pd–In2O3 CP stability, after 500 h | E38: CO2 conversion | F38: 9.2 | G38: % | H38: = | I38: 9.2 | J38: 9.2 | L38: =J38 -> 9.2 | M38: =I38-L38 -> 0 | N38: =IF(ABS(M38)<0.0000001,"MATCH","MISMATCH") -> MATCH | O38: 直接印刷/单位等价 | P38: Y: 原文表/正文/图注明确数字 | Q38: 9.7 to 9.2%, stable until 500h | R38: PDF第8页 | S38: Fig.6 stability text CO2 conversion after 200h | T38: 原文数值及工况相符 | U38: https://drive.google.com/file/d/1SpUJIHvYqa2nrDV6DeXCxRVpO02YyOJ1/view | V38: ee86dd4c833be2702f5e825c66a6dd3b1cc8c609bd9cc441ee955a26b3cd5330 | W38: Frei-main
A39: 38 | B39: 10.1038/s41467-019-11349-9 | C39: CP | D39: Fig. 6/text Pd–In2O3 CP stability, start | E39: temperature | F39: 279.85 | G39: °C (from K) | I39: 279.85 | J39: 553 | L39: =ROUND(J39-273.15,2) -> 279.85 | M39: =I39-L39 -> 0 | N39: =IF(ABS(M39)<0.0000001,"MATCH","MISMATCH") -> MATCH | O39: 直接印刷/单位等价 | P39: Y: 原文数字直印；已换算单位 | Q39: 553 K | R39: PDF第8页 | S39: Fig.6 stability caption, T | T39: 原文数值及工况相符 | U39: https://drive.google.com/file/d/1SpUJIHvYqa2nrDV6DeXCxRVpO02YyOJ1/view | V39: ee86dd4c833be2702f5e825c66a6dd3b1cc8c609bd9cc441ee955a26b3cd5330 | W39: Frei-main
A40: 39 | B40: 10.1038/s41467-019-11349-9 | C40: CP | D40: Fig. 6/text Pd–In2O3 CP stability, start | E40: pressure | F40: 50 | G40: bar | I40: 50 | J40: 5 | L40: =J40*10 -> 50 | M40: =I40-L40 -> 0 | N40: =IF(ABS(M40)<0.0000001,"MATCH","MISMATCH") -> MATCH | O40: 直接印刷/单位等价 | P40: Y: 原文数字直印；已换算单位 | Q40: P=5 MPa | R40: PDF第8页 | S40: Fig.6 stability caption, P | T40: 原文数值及工况相符 | U40: https://drive.google.com/file/d/1SpUJIHvYqa2nrDV6DeXCxRVpO02YyOJ1/view | V40: ee86dd4c833be2702f5e825c66a6dd3b1cc8c609bd9cc441ee955a26b3cd5330 | W40: Frei-main
...

Sheet 说明
A1: 甲醇文献抽取：人工金标准核对表
A3: 抽样规则（抽样前固定，见 analysis/verify_2026_10_08/gold_standard_sample.py）：
A4: 总体 = 只用印刷值时进入甲醇主结果的全部数值：2222 个数，307 个条目，28 篇论文。
A5: 随机种子 20261008：先随机抽 10 篇论文，每篇随机抽 10 个数，共 100 个数。
A7: 核对方法（必须本人对照原文或 SI 完成，不用任何程序或模型判断）：
A8: 1. 打开 pdf / si 列给出的文件（位于 agent/extraction/ 下，已下载的工作目录中），按 entry、record_location、record_page 找到该条目。
A9: 2. found_where：写出这个数在原文印刷的位置（如 'Table 2, p.5' 或 'SI Table S3'）。
A10: 3. value_in_paper：抄下原文印刷的数（原单位）。
A11: 4. printed_number：原文是印刷的数字填 Y；只能从图上读填 N。
A12: 5. judgment：correct = 换算单位后与原文一致；rounding = 只在原文印刷位数之外有差；wrong = 不一致。
A13: 6. note：其他说明（如单位换算、原文自相矛盾）。
A15: 字段说明：temperature 已从 K 换算成 °C；pressure 单位 bar（1 MPa = 10 bar）；
A16: STY (printed) 和 space velocity 给的是原文写法（as printed）。

Sheet 核对表
A1: id | B1: doi | C1: catalyst | D1: entry | E1: field | F1: extracted | G1: unit | H1: record_location | I1: record_page | J1: value_source | K1: filled | L1: pdf | M1: si | N1: found_where | O1: value_in_paper | P1: printed_number | Q1: judgment | R1: note
A2: 1 | B2: 10.1016/j.apcata.2018.04.036 | C2: 0.5Ca5P5ZC | D2: Fig 10a,b/text, 0.5Ca5P5ZC, 270 °C | E2: H2/CO2 | F2: 3 | G2: mol/mol | H2: Text Section 4 and Figure 10a,b | I2: 8 | L2: pdf/Malik_2018_Development of highly selective PdZnCeO2 and Ca-doped PdZnCeO2 catalysts for met.pdf | M2: si/10_1016_j_apcata_2018_04_036__mmc1.docx
A3: 2 | B3: 10.1016/j.apcata.2018.04.036 | C3: 5P5ZC | D3: Table 6, 5P5ZC, 220 °C | E3: CO selectivity | F3: 0 | G3: % | H3: Table 6 | I3: 8 | J3: table | L3: pdf/Malik_2018_Development of highly selective PdZnCeO2 and Ca-doped PdZnCeO2 catalysts for met.pdf | M3: si/10_1016_j_apcata_2018_04_036__mmc1.docx
A4: 3 | B4: 10.1016/j.apcata.2018.04.036 | C4: 5P5ZC | D4: Table 6, 5P5ZC, 220 °C | E4: pressure | F4: 30 | G4: bar | H4: Table 6 | I4: 8 | L4: pdf/Malik_2018_Development of highly selective PdZnCeO2 and Ca-doped PdZnCeO2 catalysts for met.pdf | M4: si/10_1016_j_apcata_2018_04_036__mmc1.docx
A5: 4 | B5: 10.1016/j.apcata.2018.04.036 | C5: 5PC | D5: Table 6, 5PC, 220 °C | E5: CH3OH selectivity | F5: 70.1 | G5: % | H5: Table 6 | I5: 8 | J5: table | L5: pdf/Malik_2018_Development of highly selective PdZnCeO2 and Ca-doped PdZnCeO2 catalysts for met.pdf | M5: si/10_1016_j_apcata_2018_04_036__mmc1.docx
A6: 5 | B6: 10.1016/j.apcata.2018.04.036 | C6: 0.5Ca5P5ZC | D6: Table 6, 0.5Ca5P5ZC, 220 °C | E6: CH4 selectivity | F6: 0 | G6: % | H6: Table 6 | I6: 8 | J6: table | L6: pdf/Malik_2018_Development of highly selective PdZnCeO2 and Ca-doped PdZnCeO2 catalysts for met.pdf | M6: si/10_1016_j_apcata_2018_04_036__mmc1.docx
A7: 6 | B7: 10.1016/j.apcata.2018.04.036 | C7: 5PC | D7: Table 6, 5PC, 220 °C | E7: H2/CO2 | F7: 3 | G7: mol/mol | H7: Table 6 | I7: 8 | L7: pdf/Malik_2018_Development of highly selective PdZnCeO2 and Ca-doped PdZnCeO2 catalysts for met.pdf | M7: si/10_1016_j_apcata_2018_04_036__mmc1.docx
A8: 7 | B8: 10.1016/j.apcata.2018.04.036 | C8: 5PC | D8: Table 6, 5PC, 220 °C | E8: CH4 selectivity | F8: 2.3 | G8: % | H8: Table 6 | I8: 8 | J8: table | L8: pdf/Malik_2018_Development of highly selective PdZnCeO2 and Ca-doped PdZnCeO2 catalysts for met.pdf | M8: si/10_1016_j_apcata_2018_04_036__mmc1.docx
A9: 8 | B9: 10.1016/j.apcata.2018.04.036 | C9: 5PC | D9: Table 6, 5PC, 220 °C | E9: CO2 conversion | F9: 1.7 | G9: % | H9: Table 6 | I9: 8 | J9: table | L9: pdf/Malik_2018_Development of highly selective PdZnCeO2 and Ca-doped PdZnCeO2 catalysts for met.pdf | M9: si/10_1016_j_apcata_2018_04_036__mmc1.docx
A10: 9 | B10: 10.1016/j.apcata.2018.04.036 | C10: 5P5ZC | D10: Table 6, 5P5ZC, 220 °C | E10: H2/CO2 | F10: 3 | G10: mol/mol | H10: Table 6 | I10: 8 | L10: pdf/Malik_2018_Development of highly selective PdZnCeO2 and Ca-doped PdZnCeO2 catalysts for met.pdf | M10: si/10_1016_j_apcata_2018_04_036__mmc1.docx
A11: 10 | B11: 10.1016/j.apcata.2018.04.036 | C11: 0.5Ca5P5ZC | D11: Table 6, 0.5Ca5P5ZC, 220 °C | E11: CO selectivity | F11: 0 | G11: % | H11: Table 6 | I11: 8 | J11: table | L11: pdf/Malik_2018_Development of highly selective PdZnCeO2 and Ca-doped PdZnCeO2 catalysts for met.pdf | M11: si/10_1016_j_apcata_2018_04_036__mmc1.docx
A12: 11 | B12: 10.1126/sciadv.abi6012 | C12: a-ZrO2 | D12: SI Table S2 row a-ZrO2 | E12: CO selectivity | F12: 26.8 | G12: % | H12: SI Table S2 | I12: 19 | J12: SI | K12: cat_mass_g<-figures | L12: pdf/Meng_2021_Oxygen-deficient metal oxides supported nano-intermetallic InNi 3 C 05 toward ef.pdf | M12: si/10_1126_sciadv_abi6012__si1.pdf
A13: 12 | B13: 10.1126/sciadv.abi6012 | C13: InNi3C0.5/t-ZrO2 | D13: Fig. 2B, InNi3C0.5/t-ZrO2, 24000 ml gcat-1 hour-1 | E13: STY (printed) | F13: 0.3 gMeOH gcat−1 hour−1 | G13: as printed | H13: Fig. 2B and Results text | I13: 3 | J13: mixed | K13: X_CO2<-si;S_MeOH<-si;S_CO<-si;S_CH4<-si | L13: pdf/Meng_2021_Oxygen-deficient metal oxides supported nano-intermetallic InNi 3 C 05 toward ef.pdf | M13: si/10_1126_sciadv_abi6012__si1.pdf
A14: 13 | B14: 10.1126/sciadv.abi6012 | C14: SiO2 | D14: SI Table S2 row SiO2 | E14: H2/CO2 | F14: 3 | G14: mol/mol | H14: SI Table S2 | I14: 19 | L14: pdf/Meng_2021_Oxygen-deficient metal oxides supported nano-intermetallic InNi 3 C 05 toward ef.pdf | M14: si/10_1126_sciadv_abi6012__si1.pdf
A15: 14 | B15: 10.1126/sciadv.abi6012 | C15: InNi3C0.5/ZnO | D15: SI Table S2 row InNi3C0.5/ZnO | E15: CO2 conversion | F15: 7.8 | G15: % | H15: SI Table S2 | I15: 19 | J15: SI | L15: pdf/Meng_2021_Oxygen-deficient metal oxides supported nano-intermetallic InNi 3 C 05 toward ef.pdf | M15: si/10_1126_sciadv_abi6012__si1.pdf
A16: 15 | B16: 10.1126/sciadv.abi6012 | C16: InNi3C0.5/TiO2 | D16: SI Table S2 row InNi3C0.5/TiO2 | E16: CH3OH selectivity | F16: 66.3 | G16: % | H16: SI Table S2 | I16: 19 | J16: SI | L16: pdf/Meng_2021_Oxygen-deficient metal oxides supported nano-intermetallic InNi 3 C 05 toward ef.pdf | M16: si/10_1126_sciadv_abi6012__si1.pdf
A17: 16 | B17: 10.1126/sciadv.abi6012 | C17: m-ZrO2 | D17: SI Table S2 row m-ZrO2 | E17: space velocity | F17: 12000 mL gcat−1 h−1 | G17: as printed | H17: SI Table S2 | I17: 19 | J17: SI | K17: cat_mass_g<-figures | L17: pdf/Meng_2021_Oxygen-deficient metal oxides supported nano-intermetallic InNi 3 C 05 toward ef.pdf | M17: si/10_1126_sciadv_abi6012__si1.pdf
A18: 17 | B18: 10.1126/sciadv.abi6012 | C18: InNi3C0.5/a-ZrO2 | D18: Fig. 2A, InNi3C0.5/a-ZrO2, 12000 ml gcat-1 hour-1 | E18: CH4 selectivity | F18: 0.4 | G18: % | H18: Fig. 2A | I18: 3 | J18: SI | K18: X_CO2<-si;S_MeOH<-si;S_CO<-si;S_CH4<-si;GHSV<-si;H2_CO2<-si | L18: pdf/Meng_2021_Oxygen-deficient metal oxides supported nano-intermetallic InNi 3 C 05 toward ef.pdf | M18: si/10_1126_sciadv_abi6012__si1.pdf
A19: 18 | B19: 10.1126/sciadv.abi6012 | C19: InNi3C0.5/m-ZrO2 | D19: Fig. 2A, InNi3C0.5/m-ZrO2, 12000 ml gcat-1 hour-1 | E19: H2/CO2 | F19: 3 | G19: mol/mol | H19: Fig. 2A and Results text | I19: 3 | K19: S_CO<-si;S_CH4<-si | L19: pdf/Meng_2021_Oxygen-deficient metal oxides supported nano-intermetallic InNi 3 C 05 toward ef.pdf | M19: si/10_1126_sciadv_abi6012__si1.pdf
A20: 19 | B20: 10.1126/sciadv.abi6012 | C20: m-ZrO2 | D20: SI Table S2 row m-ZrO2 | E20: temperature | F20: 300 | G20: °C (from K) | H20: SI Table S2 | I20: 19 | K20: cat_mass_g<-figures | L20: pdf/Meng_2021_Oxygen-deficient metal oxides supported nano-intermetallic InNi 3 C 05 toward ef.pdf | M20: si/10_1126_sciadv_abi6012__si1.pdf
A21: 20 | B21: 10.1126/sciadv.abi6012 | C21: InNi3C0.5/Fe3O4 | D21: Text/Table S7, InNi3C0.5/Fe3O4, 325C, 4.0 MPa, H2/CO2 8:1, GHSV 30000 | E21: pressure | F21: 40 | G21: bar | H21: Results text, Tailoring more advanced InNi3C0.5 catalyst | I21: 6 | K21: S_CO<-si;STY<-si | L21: pdf/Meng_2021_Oxygen-deficient metal oxides supported nano-intermetallic InNi 3 C 05 toward ef.pdf | M21: si/10_1126_sciadv_abi6012__si1.pdf
A22: 21 | B22: 10.1039/c2cy20604h | C22: Cu–Ba/Al2O3 | D22: Text, Cu-Ba/Al2O3, 443 K, 36 MPa | E22: temperature | F22: 169.85 | G22: °C (from K) | H22: Text discussing methyl formate formation | I22: 7 | K22: X_CO2<-si;S_MeOH<-si;S_CO<-si;STY<-si | L22: pdf/Bansode_2013_Impact of K and Ba promoters on CO 2 hydrogenation over CuAl 2 O 3 catalysts at.pdf | M22: si/10_1039_c2cy20604h__si1.pdf
A23: 22 | B23: 10.1039/c2cy20604h | C23: Cu–Ba/Al2O3 | D23: SI Table 3, 503 K, 36 MPa | E23: STY (printed) | F23: 56.5 mg gcat-1 h-1 | G23: as printed | H23: SI Table 3 | I23: 4 | J23: SI | L23: pdf/Bansode_2013_Impact of K and Ba promoters on CO 2 hydrogenation over CuAl 2 O 3 catalysts at.pdf | M23: si/10_1039_c2cy20604h__si1.pdf
A24: 23 | B24: 10.1039/c2cy20604h | C24: Cu–Ba/Al2O3 | D24: SI Table 3, 533 K, 0.4 MPa | E24: CH3OH selectivity | F24: 4.4 | G24: % | H24: SI Table 3 | I24: 4 | J24: SI | L24: pdf/Bansode_2013_Impact of K and Ba promoters on CO 2 hydrogenation over CuAl 2 O 3 catalysts at.pdf | M24: si/10_1039_c2cy20604h__si1.pdf
A25: 24 | B25: 10.1039/c2cy20604h | C25: Cu/Al2O3 | D25: Fig 5/Fig 6, Cu/Al2O3, 443 K, 10 MPa | E25: CH3OH selectivity | F25: 80 | G25: % | H25: Figure 5 and text on page 7 | I25: 6 | J25: mixed | K25: X_CO2<-si;S_CO<-si;STY<-si;GHSV<-figures | L25: pdf/Bansode_2013_Impact of K and Ba promoters on CO 2 hydrogenation over CuAl 2 O 3 catalysts at.pdf | M25: si/10_1039_c2cy20604h__si1.pdf
A26: 25 | B26: 10.1039/c2cy20604h | C26: Cu–K/Al2O3 | D26: Fig 7, Cu-K/Al2O3, 533 K, 36 MPa | E26: STY (printed) | F26: 10.6 mg gcat-1 h-1 | G26: as printed | H26: Figure 7 | I26: 7 | J26: SI | K26: X_CO2<-si;S_MeOH<-si;S_CO<-si;STY<-si;H2_CO2<-si;GHSV<-figures | L26: pdf/Bansode_2013_Impact of K and Ba promoters on CO 2 hydrogenation over CuAl 2 O 3 catalysts at.pdf | M26: si/10_1039_c2cy20604h__si1.pdf
A27: 26 | B27: 10.1039/c2cy20604h | C27: Cu–Ba/Al2O3 | D27: SI Table 3, 553 K, 0.4 MPa | E27: CO selectivity | F27: 98.1 | G27: % | H27: SI Table 3 | I27: 4 | J27: SI | L27: pdf/Bansode_2013_Impact of K and Ba promoters on CO 2 hydrogenation over CuAl 2 O 3 catalysts at.pdf | M27: si/10_1039_c2cy20604h__si1.pdf
A28: 27 | B28: 10.1039/c2cy20604h | C28: Cu–Ba/Al2O3 | D28: SI Table 3, 443 K, 0.4 MPa | E28: CO selectivity | F28: 72.5 | G28: % | H28: SI Table 3 | I28: 4 | J28: SI | L28: pdf/Bansode_2013_Impact of K and Ba promoters on CO 2 hydrogenation over CuAl 2 O 3 catalysts at.pdf | M28: si/10_1039_c2cy20604h__si1.pdf
A29: 28 | B29: 10.1039/c2cy20604h | C29: Cu–Ba/Al2O3 | D29: Fig 8, Cu-Ba/Al2O3, 473 K, 10 MPa | E29: temperature | F29: 199.85 | G29: °C (from K) | H29: Figure 8 and abstract | I29: 7 | K29: X_CO2<-si;S_CO<-si;STY<-si;GHSV<-figures | L29: pdf/Bansode_2013_Impact of K and Ba promoters on CO 2 hydrogenation over CuAl 2 O 3 catalysts at.pdf | M29: si/10_1039_c2cy20604h__si1.pdf
A30: 29 | B30: 10.1039/c2cy20604h | C30: Cu–K/Al2O3 | D30: Fig 7/Fig 8, Cu-K/Al2O3, 473 K, 36 MPa | E30: CO2 conversion | F30: 8.9 | G30: % | H30: Figure 7 and Figure 8 | I30: 7 | J30: SI | K30: X_CO2<-si;S_MeOH<-si;S_CO<-si;STY<-si;H2_CO2<-si;GHSV<-figures | L30: pdf/Bansode_2013_Impact of K and Ba promoters on CO 2 hydrogenation over CuAl 2 O 3 catalysts at.pdf | M30: si/10_1039_c2cy20604h__si1.pdf
A31: 30 | B31: 10.1039/c2cy20604h | C31: Cu–K/Al2O3 | D31: Fig 7, Cu-K/Al2O3, 533 K, 3 MPa | E31: CO selectivity | F31: 98.1 | G31: % | H31: Figure 7 | I31: 7 | J31: SI | K31: X_CO2<-si;S_MeOH<-si;S_CO<-si;STY<-si;H2_CO2<-si;GHSV<-figures | L31: pdf/Bansode_2013_Impact of K and Ba promoters on CO 2 hydrogenation over CuAl 2 O 3 catalysts at.pdf | M31: si/10_1039_c2cy20604h__si1.pdf
A32: 31 | B32: 10.1038/s41467-019-11349-9 | C32: Pd–In2O3 CP | D32: Table 2 Pd–In2O3 CP, WHSV 48,000 initial | E32: pressure | F32: 50 | G32: bar | H32: Table 2 | I32: 9 | L32: pdf/Frei_2019_Atomic-scale engineering of indium oxide promotion by palladium for methanol pro.pdf | M32: si/10_1038_s41467_019_11349_9__si1.pdf; si/10_1038_s41467_019_11349_9__si2.pdf
A33: 32 | B33: 10.1038/s41467-019-11349-9 | C33: CP | D33: Fig. 6/text Pd–In2O3 CP stability, start | E33: CH3OH selectivity | F33: 75 | G33: % | H33: Fig. 6 and Results text | I33: 8 | J33: mixed | L33: pdf/Frei_2019_Atomic-scale engineering of indium oxide promotion by palladium for methanol pro.pdf | M33: si/10_1038_s41467_019_11349_9__si1.pdf; si/10_1038_s41467_019_11349_9__si2.pdf
A34: 33 | B34: 10.1038/s41467-019-11349-9 | C34: Pd–In2O3 CP | D34: Table 2 Pd–In2O3 CP, WHSV 48,000 initial | E34: temperature | F34: 279.85 | G34: °C (from K) | H34: Table 2 | I34: 9 | L34: pdf/Frei_2019_Atomic-scale engineering of indium oxide promotion by palladium for methanol pro.pdf | M34: si/10_1038_s41467_019_11349_9__si1.pdf; si/10_1038_s41467_019_11349_9__si2.pdf
A35: 34 | B35: 10.1038/s41467-019-11349-9 | C35: CP | D35: Fig. 6/text Pd–In2O3 CP stability, after 500 h | E35: temperature | F35: 279.85 | G35: °C (from K) | H35: Fig. 6 and Results text | I35: 8 | L35: pdf/Frei_2019_Atomic-scale engineering of indium oxide promotion by palladium for methanol pro.pdf | M35: si/10_1038_s41467_019_11349_9__si1.pdf; si/10_1038_s41467_019_11349_9__si2.pdf
A36: 35 | B36: 10.1038/s41467-019-11349-9 | C36: CP | D36: Fig. 6/text Pd–In2O3 CP stability, start | E36: CO2 conversion | F36: 9.7 | G36: % | H36: Fig. 6 and Results text | I36: 8 | J36: mixed | L36: pdf/Frei_2019_Atomic-scale engineering of indium oxide promotion by palladium for methanol pro.pdf | M36: si/10_1038_s41467_019_11349_9__si1.pdf; si/10_1038_s41467_019_11349_9__si2.pdf
A37: 36 | B37: 10.1038/s41467-019-11349-9 | C37: CP | D37: Fig. 6/text Pd–In2O3 CP stability, start | E37: H2/CO2 | F37: 4 | G37: mol/mol | H37: Fig. 6 and Results text | I37: 8 | L37: pdf/Frei_2019_Atomic-scale engineering of indium oxide promotion by palladium for methanol pro.pdf | M37: si/10_1038_s41467_019_11349_9__si1.pdf; si/10_1038_s41467_019_11349_9__si2.pdf
A38: 37 | B38: 10.1038/s41467-019-11349-9 | C38: CP | D38: Fig. 6/text Pd–In2O3 CP stability, after 500 h | E38: CO2 conversion | F38: 9.2 | G38: % | H38: Fig. 6 and Results text | I38: 8 | J38: mixed | L38: pdf/Frei_2019_Atomic-scale engineering of indium oxide promotion by palladium for methanol pro.pdf | M38: si/10_1038_s41467_019_11349_9__si1.pdf; si/10_1038_s41467_019_11349_9__si2.pdf
A39: 38 | B39: 10.1038/s41467-019-11349-9 | C39: CP | D39: Fig. 6/text Pd–In2O3 CP stability, start | E39: temperature | F39: 279.85 | G39: °C (from K) | H39: Fig. 6 and Results text | I39: 8 | L39: pdf/Frei_2019_Atomic-scale engineering of indium oxide promotion by palladium for methanol pro.pdf | M39: si/10_1038_s41467_019_11349_9__si1.pdf; si/10_1038_s41467_019_11349_9__si2.pdf
A40: 39 | B40: 10.1038/s41467-019-11349-9 | C40: CP | D40: Fig. 6/text Pd–In2O3 CP stability, start | E40: pressure | F40: 50 | G40: bar | H40: Fig. 6 and Results text | I40: 8 | L40: pdf/Frei_2019_Atomic-scale engineering of indium oxide promotion by palladium for methanol pro.pdf | M40: si/10_1038_s41467_019_11349_9__si1.pdf; si/10_1038_s41467_019_11349_9__si2.pdf
...

Sheet 具体修订与边界
A1: 问题ID | B1: 具体字段 | C1: 原文证据 | D1: 严格评价 | E1: 必须修订 | F1: 对主结论的含义
A2: 45,79,85,90 | B2: H2/CO2 | C2: 原文给的是多组分 H2/CO2/N2 73/24/3；66/22/12；60/20/20 | D2: 数值准确、字段不直接印刷 | E2: source_type=derived；存储feedcomposition三分量与计算式 | F2: 论文方法需明示选择气组成转换口径
A3: 95,96 | B3: H2/CO2 | C3: Ota Table2给CO2:H2=1:3 | D3: 倒序转换值正确 | E3: raw_value=CO2:H2 1:3，normalized_H2/CO2=3 | F3: 避免将倒序比描述成原文直接写H2/CO2
A4: 40 | B4: CO2 conversion 9.7% | C4: Frei正文Fig.6附近给9.7%，Table2无CO2 conversion列 | D4: 数值匹配、定位错误 | E4: 改found_where为Main text near Fig.6 (PDF p8) | F4: 保证审稿人按索引能找到来源
A5: 93 | B5: CH4 selectivity <0.1% | C5: Ota正文 methods: traces (less than 0.1% selectivity) of methane | D5: 上界不是实测0.1% | E5: 源表增加qualifier列并保留<；改定位为正文p3；不填exact 0.1 | F5: 必须作为censored/upper-bound输入处理
A6: 99 | B6: STY (printed) 0.3 | C6: Ota Table2列标题Rate, MeOH=0.3 µmol/(gcat min) | D6: 值匹配、列名应审计 | E6: 保留原量纲并标注original_label=Rate而非直接定义为质量STY | F6: 影响跨论文单位汇总风险
A7: 32 | B7: CH3OH selectivity 75% | C7: Frei正文Fig6稳定性初期75→78%；Table2另给初始78% | D7: 按实验序列分组两者均有各自来源 | E7: 区分Table2测量口径和500h稳定性序列 | F7: 同论文不能把两初始值当成相同运行点
A8: 10篇论文的条件字段 | B8: 重复P/T/H2/CO2 | C8: 同论文Table caption/common conditions跨多行共享 | D8: 源数值支持，但并非独立实验观测 | E8: 论文级cluster统计；分开性能与条件字段 | F8: 不能把100条当独立验证样本
A9: 未抽到的Bansode压力 | B9: 36MPa与36bar | C9: 原始SI 0.4/3/10/36 MPa | D9: 存在100条样本之外的外部数据库勘误风险 | E9: 与独立errata sheet交叉核，必要时回溯模型输入 | F9: 100条样本通过也不等于数据总体无单位错误
A10: Malik原论文文本内部 | B10: 7.6% vs 7.7% | C10: 正文4节7.6%但Table6 0.5Ca5P5ZC为7.7% | D10: 文献内部冲突；非此次100抽样字段 | E10: 主模型若使用此行优先采用表格印刷值并备注冲突 | F10: 需审计模型引用来源
A11: 审计资格 | B11: 100项AI依据 | C11: 已有10篇主文、原始SI部分全部可获取 | D11: AI辅助原文独立复核，不是人类双盲人工签字 | E11: 保留人工判定栏空白，请检查者复签 | F11: 论文摘要不能报告“100项已人工核验”

Sheet Drive原始文件与SHA256
A1: 来源KEY | B1: 类型 | C1: 文件名 | D1: Google Drive 原始地址 | E1: SHA256 | F1: 字节数 | G1: 用于核验的ID | H1: 注释
A2: Malik-main | B2: 论文正文 | C2: Malik_2018_Development of highly selective PdZnCeO2 and Ca-doped PdZnCeO2 catalysts for met.pdf | D2: https://drive.google.com/file/d/1--kU_GkfzNu3dB71N5o_RA6ri2lVgEcj/view | E2: 58e4e1e6d1ae981bc27217fd90ac31d34660d313ce095820052e13d7c065e1ab | F2: 3141275 | G2: 1, 2, 3, 4, 5, 6, 7, 8, 9, 10 | H2: 源为Google Drive 2026-10-12下载的原始PDF；哈希用于离线再核
A3: Meng-main | B3: 论文正文 | C3: Meng_2021_Oxygen-deficient metal oxides supported nano-intermetallic InNi 3 C 05 toward ef.pdf | D3: https://drive.google.com/file/d/1R7gbS2sdMmPWvqKsrC6fKUXSedvwZfwe/view | E3: c227d1c10d8ff9c77df8e7a2b1466afeb6e2aa272c436fcb2db7e55e2e5bbb37 | F3: 4397358 | H3: 源为Google Drive 2026-10-12下载的原始PDF；哈希用于离线再核
A4: Meng-SI | B4: 补充材料 | C4: 10_1126_sciadv_abi6012__si1.pdf | D4: https://drive.google.com/file/d/1w4nbo1f-SQjZ1_mP63Uc7HuFbekYMUyA/view | E4: ebff6b65cec05a24ea067333c5cb805b9dcc83408f1205ac2781c578bde9b866 | F4: 1971321 | G4: 11, 12, 13, 14, 15, 16, 17, 18, 19, 20 | H4: 源为Google Drive 2026-10-12下载的原始PDF；哈希用于离线再核
A5: Bansode-main | B5: 论文正文 | C5: Bansode_2013_Impact of K and Ba promoters on CO 2 hydrogenation over CuAl 2 O 3 catalysts at.pdf | D5: https://drive.google.com/file/d/1mHfxFIRroGBoD_rc-z2M0IDdER6fIXCu/view | E5: 054321b0b5a4205745554b74263095b1d7e7da947bf51c24b395fc1c8b8e66f4 | F5: 2623357 | H5: 源为Google Drive 2026-10-12下载的原始PDF；哈希用于离线再核
A6: Bansode-SI | B6: 补充材料 | C6: 10_1039_c2cy20604h__si1.pdf | D6: https://drive.google.com/file/d/1vAP6iNS7sXYNV2z9__QqhMEJt5o0Rllo/view | E6: 9a45c3d5c0555001a60b3b6485b3a9799500a57079fc266f8cdf0562ad5ebcf0 | F6: 482039 | G6: 21, 22, 23, 24, 25, 26, 27, 28, 29, 30 | H6: 源为Google Drive 2026-10-12下载的原始PDF；哈希用于离线再核
A7: Frei-main | B7: 论文正文 | C7: Frei_2019_Atomic-scale engineering of indium oxide promotion by palladium for methanol pro.pdf | D7: https://drive.google.com/file/d/1SpUJIHvYqa2nrDV6DeXCxRVpO02YyOJ1/view | E7: ee86dd4c833be2702f5e825c66a6dd3b1cc8c609bd9cc441ee955a26b3cd5330 | F7: 1929397 | G7: 31, 32, 33, 34, 35, 36, 37, 38, 39, 40 | H7: 源为Google Drive 2026-10-12下载的原始PDF；哈希用于离线再核
A8: Dang-main | B8: 论文正文 | C8: Dang_2020_Rationally designed indium oxide catalysts for CO 2 hydrogenation to methanol wi.pdf | D8: https://drive.google.com/file/d/1JtMfT_rmaSxPBxw9ruJKSfhUJnyYMn_-/view | E8: 3d5da02d49915def0108f56f6123b1ca1800e65b600dd725e62976e16d76c001 | F8: 3328812 | G8: 41, 42, 43, 44, 45, 46, 47, 48, 49, 50 | H8: 源为Google Drive 2026-10-12下载的原始PDF；哈希用于离线再核
A9: Gao-main | B9: 论文正文 | C9: Gao_2015_Yttrium oxide modified CuZnOAl 2 O 3 catalysts via hydrotalcite-like precursors.pdf | D9: https://drive.google.com/file/d/1GvzHIPGbmfYxz-tsqbDLSeqcKO2SJdg_/view | E9: e614d670a66fff90bbd3335c090e5ea6684d3878219e2f4ef82fb3a6dbde0f17 | F9: 2532875 | G9: 51, 52, 53, 54, 55, 56, 57, 58, 59, 60 | H9: 源为Google Drive 2026-10-12下载的原始PDF；哈希用于离线再核
A10: Rui-main | B10: 论文正文 | C10: Rui_2017_CO2 hydrogenation to methanol over PdIn2O3 effects of Pd and oxygen vacancy.pdf | D10: https://drive.google.com/file/d/1DEiVdM2jAEkQfVRPNXrNGIaDkYmHYJJI/view | E10: 364513a2b867a26d104e502c3ae8503d3a7c38aef5a592fccffa29cc937baf43 | F10: 2506110 | G10: 68, 69 | H10: 源为Google Drive 2026-10-12下载的原始PDF；哈希用于离线再核
A11: Rui-SI | B11: 补充材料 | C11: 10_1016_j_apcatb_2017_06_069__mmc1.pdf | D11: https://drive.google.com/file/d/1AIgTxerbhuj424LzfNw0_t3wwBf0Iu3I/view | E11: 11f8f70b20cde4f9240f45948ebd9defe54bc22db1b4f40da0efd9ac323c52dc | F11: 835712 | G11: 61, 62, 63, 64, 65, 66, 67, 70 | H11: 源为Google Drive 2026-10-12下载的原始PDF；哈希用于离线再核
A12: Chen-main | B12: 论文正文 | C12: Chen_2019_MorphologyControllable HexagonalPhase Indium Oxide In Situ Structured onto a Thi.pdf | D12: https://drive.google.com/file/d/1KWB194YdzohFxLovrjrNmdHyvch8n70q/view | E12: 84885c9b5347bdf321cfb342c5d3b171245f051b72f0cdec173551fb81b08b41 | F12: 2108746 | H12: 源为Google Drive 2026-10-12下载的原始PDF；哈希用于离线再核
A13: Chen-SI | B13: 补充材料 | C13: 10_1002_ente_201800747__si1.pdf | D13: https://drive.google.com/file/d/1BfPoG96bC3lh69paQTz4qlQDV83XHTdg/view | E13: 28de9ff027971d177773816fc9cc1e8a9e15485eb853b79fddb0085b349fd148 | F13: 638567 | G13: 71, 72, 73, 74, 75, 76, 77, 78, 79, 80 | H13: 源为Google Drive 2026-10-12下载的原始PDF；哈希用于离线再核
A14: Ruiz-main | B14: 论文正文 | C14: RuizEsquius_2020_CO 2 Hydrogenation to CH 3 OH over PdZn Catalysts with Reduced CH 4 Production.pdf | D14: https://drive.google.com/file/d/1KbcBNcn6Fu7BYiqMz1i33vxyVC5fyj1R/view | E14: 940fa897226c94da235dcd577a399b06494f3c01b4aeaf87b2e2524c7c6c75d9 | F14: 1045649 | G14: 82, 90 | H14: 源为Google Drive 2026-10-12下载的原始PDF；哈希用于离线再核
A15: Ruiz-SI | B15: 补充材料 | C15: 10_1002_cctc_202000974__si1.pdf | D15: https://drive.google.com/file/d/1UGQFZ9fnewpti0zvdYyWSXMRrpTxP5qR/view | E15: 4f24221d4806514e846c73139d2d2628e34fae727a401b9b85e1451ff27d812a | F15: 1233326 | G15: 81, 83, 84, 85, 86, 87, 88, 89 | H15: 源为Google Drive 2026-10-12下载的原始PDF；哈希用于离线再核
A16: Ota-main | B16: 论文正文 | C16: Ota_2012_Comparative study of hydrotalcite-derived supported Pd2Ga and PdZn intermetallic.pdf | D16: https://drive.google.com/file/d/1GyR6wSTnSFGhsz4xd2mT6pW_gvLdq-ZD/view | E16: f4e6a0fb755e2b61dc77aed734014bc754e90c277a5e47b9e1767a0aaeffc16b | F16: 2100512 | G16: 91, 92, 93, 94, 95, 96, 97, 98, 99, 100 | H16: 源为Google Drive 2026-10-12下载的原始PDF；哈希用于离线再核
A17: 额外SI文件 | B17: 补充材料 | C17: 已另保存/检查 F re i / Dang / Gao / Ota / Malik 的额外SI 文件 | H17: 本表列出与100值有直接证据依赖关系的15份PDF
