Workbook

Sheet README
A1: Ammonia activity volcano — Dataset S1 / MKM V1
A2: Wang & Abild-Pedersen (PNAS 2021) supplementary energetics → step-site scaling/BEP → reduced mean-field microkinetics → TOF
A4: Scope | B4: This workbook builds a genuine descriptor–activity volcano: x = step-site N formation energy E_N; y = log10 NH3 TOF. It is no longer the literature-guided schematic volcano.
A5: Source data | B5: Uploaded Dataset S1 (pnas.2106527118.sd01.txt). Parsed table contains 444 energetic rows across terrace, step_site, confined_site and gas.
A6: Critical completeness finding | B6: Dataset S1 contains complete 10-species step-site energetics for 14 metals, but no Fe step_site rows. Fe terrace E_N is present; Fe step E_N is therefore estimated from the 14-metal terrace→step E_N regression. All other Fe step energetics are then generated from the 14-metal step scaling fits.
A7: Main activity volcano | B7: The main volcano is a one-descriptor model. For each metal, only step E_N locates it on the x-axis; H, N2, NHx and four TS energies are generated by S1-derived linear scaling relations. This makes the curve internally consistent and gives Ru/Os near the optimum with Fe on the strong-binding side.
A8: MKM conditions | B8: T=673 K; p(N2)=24.5 bar; p(H2)=74.25 bar; p(NH3)=1 bar. Adsorbate/TS vibrational free energies use S1 frequencies; gases use ideal-gas statistical thermodynamics at 1 bar standard state.
A9: Model status | B9: MKM V1 is a transparent reduced one-site mean-field reconstruction using explicit S1 TS energies/scaling and detailed balance. It is not claimed to reproduce the paper’s CatMAP implementation or its absolute TOFs exactly.
A10: Headline result | B10: Smooth 1D optimum: E_N ≈ -1.175 eV. Descriptor-based ranking starts Ru > Os > Fe. See MKM_15 and Volcano_1D.
A11: What to use in group meeting | B11: Use the main PNG / Volcano_1D figure and the Step_15_Energetics + Scaling_Fits sheets. Direct_DFT_Check is a diagnostic showing departures from the strict 1D scaling manifold, not the headline ranking.
A13: Primary article URL | B13: https://doi.org/10.1073/pnas.2106527118
A14: PMC full text | B14: https://pmc.ncbi.nlm.nih.gov/articles/PMC8325328/
A15: Uploaded S1 | B15: pnas.2106527118.sd01.txt
A16: Reproducible solver | B16: mkm_s1_activity_v2.py

Sheet S1_All_444
A1: Dataset S1 — parsed formation-energy table
A2: Direct parse of the uploaded supplementary TXT. Frequencies are retained as supplied; formation energies are in eV.
A4: surface | B4: phase | C4: site | D4: species | E4: formation_energy_eV | F4: frequencies_meV | G4: reference | H4: coverage | I4: std
A5: Ag | B5: terrace | D5: H | E5: 0.2881 | F5: [83.0, 83.2, 97.7] | G5: 65 | H5: 0.25
A6: Ag | B6: terrace | D6: N | E6: 2.9765 | F6: [45.5, 45.5, 46.5] | G6: 47 | H6: 0.25
A7: Ag | B7: terrace | D7: N-H | E7: 4.1409 | F7: [31.3, 42.2, 45.8, 65.2, 142.1] | G7: 150 | H7: 0.25
A8: Ag | B8: terrace | D8: N2 | E8: -0.0978 | F8: [1.9, 1.5, 3.7, 4.0, 6.1, 298.2] | G8: 40 | H8: 0.25
A9: Ag | B9: terrace | D9: N-N | E9: 6.4811 | F9: [42.5, 52.7, 55.1, 56.7, 59.3] | G9: notsure | H9: 0.25
A10: Ag | B10: terrace | D10: NH | E10: 1.2327 | F10: [42.5, 42.5, 46.8, 73.4, 73.4, 435.1] | G10: 101 | H10: 0.25
A11: Ag | B11: terrace | D11: NH-H | E11: 2.5534 | F11: [27.7, 36.3, 44.0, 55.8, 66.6, 78.6, 133.3, 429.6] | G11: 125 | H11: 0.25
A12: Ag | B12: terrace | D12: NH2 | E12: 0.0122 | F12: [12.3, 29.1, 40.9, 58.5, 62.4, 63.1, 185.7, 432.5, 445.4] | G12: 33 | H12: 0.25
A13: Ag | B13: terrace | D13: NH2-H | E13: 1.3437 | F13: [13.2, 21.4, 32.3, 46.2, 60.3, 88.7, 102.8, 138.2, 185.9, 422.1, 435.9] | G13: 137 | H13: 0.25
A14: Ag | B14: terrace | D14: NH3 | E14: -1.0219 | F14: [15.0, 5.4, 6.2, 13.8, 36.2, 36.2, 128.2, 200.4, 200.7, 429.6, 447.4, 447.8] | G14: 104 | H14: 0.25
A15: Au | B15: terrace | D15: H | E15: 0.031 | F15: [73.2, 73.3, 94.3] | G15: 58 | H15: 0.25
A16: Au | B16: terrace | D16: N | E16: 2.3914 | F16: [48.9, 53.5, 53.6] | G16: 32 | H16: 0.25
... A80: Ni | B80: terrace | D80: NH3 | E80: -1.295 | F80: [10, 10.8, 10.8, 28.0, 61.5, 61.5, 136.3, 197.7, 198.2, 424.7, 441.8, 442.2] | G80: 31 | H80: 0.25
C81: gas | D81: H2 | E81: 0 | F81: [550] | G81: 1 | H81: 0
C82: gas | D82: NH3 | E82: -0.7411 | F82: [435.8, 435.56, 420.43, 200.36, 200.23, 125.47] | G82: 2 | H82: 0
C83: gas | D83: N2 | E83: 0 | F83: [340] | G83: 3 | H83: 0
A84: Os | B84: terrace | D84: H | E84: -0.3248 | F84: [89.1, 89.3, 135.0] | G84: 63 | H84: 0.25
A85: Os | B85: terrace | D85: N | E85: -0.7404 | F85: [57.3, 59.6, 71.3] | G85: 45 | H85: 0.25
A86: Os | B86: terrace | D86: N-H | E86: 0.1038 | F86: [44.2, 55.5, 67.2, 68.8, 212.0] | G86: 143 | H86: 0.25
A87: Os | B87: terrace | D87: N-N | E87: 1.8558 | F87: [24.5, 40.0, 48.6, 69.0, 73.0] | G87: 108 | H87: 0.25
A88: Os | B88: terrace | D88: N2 | E88: -0.4454 | F88: [9.1, 9.5, 40.4, 46.0, 46.1, 271.4] | G88: 59 | H88: 0.25
A89: Os | B89: terrace | D89: NH | E89: -1.1201 | F89: [53.3, 54.1, 68.3, 92.2, 92.8, 437.8] | G89: 73 | H89: 0.25
A90: Os | B90: terrace | D90: NH-H | E90: -0.0695 | F90: [45.4, 46.1, 60.8, 67.7, 86.6, 134.2, 224.4, 432.5] | G90: 118 | H90: 0.25
A91: Os | B91: terrace | D91: NH2 | E91: -1.0846 | F91: [25.8, 34.3, 57.6, 85.9, 88.0, 92.3, 191.0, 429.4, 441.3] | G91: 86 | H91: 0.25
A92: Os | B92: terrace | D92: NH2-H | E92: -0.0653 | F92: [17.8, 13.2, 16.1, 52.5, 57.9, 64.9, 87.0, 108.1, 185.8, 434.3, 449.7] | G92: 131 | H92: 0.25
A93: Os | B93: terrace | D93: NH3 | E93: -1.6069 | F93: [12.7, 16.0, 16.2, 40.8, 76.1, 77.9, 145.2, 197.5, 198.0, 424.5, 441.0, 441.7] | G93: 26 | H93: 0.25
A94: Pd | B94: terrace | D94: H | E94: -0.3238 | F94: [95.3, 95.4, 114.1] | G94: 66 | H94: 0.25
A95: Pd | B95: terrace | D95: N | E95: 0.8054 | F95: [58.3, 58.4, 58.4] | G95: 53 | H95: 0.25
... A111: Pt | B111: terrace | D111: NH2 | E111: -0.7258 | F111: [25.7, 39.8, 56.0, 82.7, 94.3, 96.7, 185.2, 431.5, 444.8] | G111: 76 | H111: 0.25
A112: Pt | B112: terrace | D112: NH2-H | E112: -0.361 | F112: [15.1, 16.6, 30.2, 43.6, 61.9, 95.9, 104.5, 183.2, 219.0, 430.2, 444.4] | G112: 138 | H112: 0.25 | I112: notsure
A113: Pt | B113: terrace | D113: NH3 | E113: -1.6519 | F113: [17.0, 12.9, 13.3, 37.4, 77.1, 77.2, 139.0, 197.1, 198.2, 429.5, 446.1, 446.5] | G113: 41 | H113: 0.25
A114: Re | B114: terrace | D114: H | E114: -0.5601 | F114: [120.1, 127.4, 135.6] | G114: 85 | H114: 0.25
A115: Re | B115: terrace | D115: N | E115: -1.4205 | F115: [54.7, 55.2, 74.8] | G115: 87 | H115: 0.25
A116: Re | B116: terrace | D116: N-H | E116: -0.542 | F116: [40.5, 48.4, 63.5, 71.8, 202.3] | G116: 145 | H116: 0.25
A117: Re | B117: terrace | D117: N2 | E117: -0.5273 | F117: [6.8, 8.2, 38.0, 43.5, 44.0, 267.8] | G117: 77 | H117: 0.25
A118: Re | B118: terrace | D118: N-N | E118: 0.65513 | F118: [25.8, 38.7, 47.7, 64.9, 69.5] | G118: 109 | H118: 0.25
A119: Re | B119: terrace | D119: NH | E119: -1.7802 | F119: [50.6, 50.9, 70.7, 87.8, 88.2, 436.0] | G119: 36 | H119: 0.25
...

Sheet Step_Raw14
A1: Raw S1 step-site energetics — 14 metals
A2: These are the step-site rows available directly in Dataset S1. Fe is intentionally absent here.
A4: Metal | B4: E_N (eV) | C4: E_H (eV) | D4: E_N2* (eV) | E4: E_N-N^TS (eV) | F4: E_NH (eV) | G4: E_N-H^TS (eV) | H4: E_NH-H^TS (eV) | I4: E_NH2 (eV) | J4: E_NH2-H^TS (eV) | K4: E_NH3 (eV)
A5: Ag | B5: 2.911 | C5: 0.381 | D5: -0.1139 | E5: 7.5906 | F5: 1.2516 | G5: 4.0242 | H5: 2.4547 | I5: -0.3377 | J5: 1.2286 | K5: -1.1523
A6: Au | B6: 3.0029 | C6: 0.2992 | D6: -0.1306 | E6: 8.9784 | F6: 1.3889 | G6: 3.8511 | H6: 2.514 | I6: -0.2835 | J6: 0.9417 | K6: -1.2005
A7: Co | B7: -0.2701 | C7: -0.2591 | D7: -0.6564 | E7: 1.9503 | F7: -0.9479 | G7: 0.3919 | H7: 0.0269 | I7: -1.4836 | J7: -0.7213 | K7: -1.6416
A8: Cu | B8: 1.2491 | C8: -0.0452 | D8: -0.1261 | E8: 4.4172 | F8: 0.0893 | G8: 2.2882 | H8: 1.3546 | I8: -1.0541 | J8: 0.2595 | K8: -1.3796
A9: Ir | B9: -0.4407 | C9: -0.5867 | D9: -0.7954 | E9: 1.099 | F9: -0.9685 | G9: 0.7265 | H9: -0.2354 | I9: -1.7381 | J9: -0.7487 | K9: -1.937
A10: Mo | B10: -1.8417 | C10: -0.7187 | D10: -1.5107 | E10: -0.9147 | F10: -2.088 | G10: -0.6237 | H10: -0.714 | I10: -2.1565 | J10: -0.7779 | K10: -1.9302
A11: Ni | B11: -0.0928 | C11: -0.3841 | D11: -0.6225 | E11: 1.4944 | F11: -0.6889 | G11: 0.8989 | H11: 0.1945 | I11: -1.5053 | J11: -0.6018 | K11: -1.6489
A12: Os | B12: -1.1095 | C12: -0.7121 | D12: -0.8328 | E12: 0.1851 | F12: -1.488 | G12: -0.0587 | H12: -0.7034 | I12: -2.0477 | J12: -0.8323 | K12: -2.0462
A13: Pd | B13: 0.5637 | C13: -0.3509 | D13: -0.3902 | E13: 4.2523 | F13: 0.0039 | G13: 1.4136 | H13: 1.0455 | I13: -0.9299 | J13: -0.1422 | K13: -1.5221
A14: Pt | B14: 0.5895 | C14: -0.4717 | D14: -0.4476 | E14: 2.4704 | F14: -0.0476 | G14: 1.34 | H14: 0.8868 | I14: -1.3007 | J14: -0.4052 | K14: -1.8103
A15: Re | B15: -1.8252 | C15: -0.8013 | D15: -1.0229 | E15: -0.7695 | F15: -1.9945 | G15: -0.3796 | H15: -1.212 | I15: -2.3639 | J15: -0.9116 | K15: -1.9839
A16: Rh | B16: -0.458 | C16: -0.4059 | D16: -0.6357 | E16: 0.9569 | F16: -0.7745 | G16: 0.5994 | H16: -0.0044 | I16: -1.4622 | J16: -0.628 | K16: -1.6682
... A18: W | B18: -2.161 | C18: -0.6777 | D18: -1.5111 | E18: -0.8249 | F18: -2.4101 | G18: -0.5697 | H18: -1.3387 | I18: -2.4821 | J18: -1.017 | K18: -2.1039

Sheet Terrace_Step_N
A1: Fe step descriptor bridge
A2: Regression of step-site E_N against terrace E_N for the 14 metals with both values. Fe terrace E_N is raw S1; Fe step E_N is the regression prediction.
A4: Metal | B4: Terrace E_N (eV) | C4: Step E_N (eV) | D4: Residual (eV) | G4: Control | H4: Value | I4: Meaning
A5: Ag | B5: 2.9765 | C5: 2.911 | D5: =C5-($H$5*B5+$H$6) -> -0.35603901 | G5: Slope | H5: =SLOPE(C5:C18,B5:B18) -> 1.1547436 | I5: step E_N = slope × terrace E_N + intercept
A6: Au | B6: 2.3914 | C6: 3.0029 | D6: =C6-($H$5*B6+$H$6) -> 0.41150149 | G6: Intercept | H6: =INTERCEPT(C5:C18,B5:B18) -> -0.17005543 | I6: eV
A7: Co | B7: -0.0986 | C7: -0.2701 | D7: =C7-($H$5*B7+$H$6) -> 0.013813154 | G7: R² | H7: =RSQ(C5:C18,B5:B18) -> 0.981813 | I7: fit quality
A8: Cu | B8: 1.0619 | C8: 1.2491 | D8: =C8-($H$5*B8+$H$6) -> 0.19293316
A9: Ir | B9: -0.0913 | C9: -0.4407 | D9: =C9-($H$5*B9+$H$6) -> -0.16521647
A10: Mo | B10: -1.5343 | C10: -1.8417 | D10: =C10-($H$5*B10+$H$6) -> 0.1000786
A11: Ni | B11: 0.0996 | C11: -0.0928 | D11: =C11-($H$5*B11+$H$6) -> -0.037757036
A12: Os | B12: -0.7404 | C12: -1.1095 | D12: =C12-($H$5*B12+$H$6) -> -0.084472379
A13: Pd | B13: 0.8054 | C13: 0.5637 | D13: =C13-($H$5*B13+$H$6) -> -0.1962751
A14: Pt | B14: 0.334 | C14: 0.5895 | D14: =C14-($H$5*B14+$H$6) -> 0.37387106
A15: Re | B15: -1.4205 | C15: -1.8252 | D15: =C15-($H$5*B15+$H$6) -> -0.01483123
A16: Rh | B16: -0.0431 | C16: -0.458 | D16: =C16-($H$5*B16+$H$6) -> -0.23817512
A17: Ru | B17: -0.7938 | C17: -1.1333 | D17: =C17-($H$5*B17+$H$6) -> -0.046609069
A18: W | B18: -1.765 | C18: -2.161 | D18: =C18-($H$5*B18+$H$6) -> 0.047177953
A20: Fe | B20: -1.0583 | C20: =$H$5*B20+$H$6 -> -1.3921206 | D20: Estimated step E_N

Sheet Step_15_Energetics
A1: 15-metal step-site energetics table
A2: 14 metals are raw Dataset S1 step energies. Fe is explicitly scaling-estimated because the uploaded S1 contains no Fe step_site rows.
A4: Metal | B4: Source method | C4: E_N (eV) | D4: E_H (eV) | E4: E_N2* (eV) | F4: E_N-N^TS (eV) | G4: E_NH (eV) | H4: E_N-H^TS (eV) | I4: E_NH-H^TS (eV) | J4: E_NH2 (eV) | K4: E_NH2-H^TS (eV) | L4: E_NH3 (eV) | M4: Note
A5: Ag | B5: S1 raw step_site | C5: 2.911 | D5: 0.381 | E5: -0.1139 | F5: 7.5906 | G5: 1.2516 | H5: 4.0242 | I5: 2.4547 | J5: -0.3377 | K5: 1.2286 | L5: -1.1523 | M5: Raw S1 step-site formation energies
A6: Au | B6: S1 raw step_site | C6: 3.0029 | D6: 0.2992 | E6: -0.1306 | F6: 8.9784 | G6: 1.3889 | H6: 3.8511 | I6: 2.514 | J6: -0.2835 | K6: 0.9417 | L6: -1.2005 | M6: Raw S1 step-site formation energies
A7: Co | B7: S1 raw step_site | C7: -0.2701 | D7: -0.2591 | E7: -0.6564 | F7: 1.9503 | G7: -0.9479 | H7: 0.3919 | I7: 0.0269 | J7: -1.4836 | K7: -0.7213 | L7: -1.6416 | M7: Raw S1 step-site formation energies
A8: Cu | B8: S1 raw step_site | C8: 1.2491 | D8: -0.0452 | E8: -0.1261 | F8: 4.4172 | G8: 0.0893 | H8: 2.2882 | I8: 1.3546 | J8: -1.0541 | K8: 0.2595 | L8: -1.3796 | M8: Raw S1 step-site formation energies
A9: Fe | B9: Scaling estimate | C9: ='Terrace_Step_N'!C20 -> -1.3921206 | D9: ='Scaling_Fits'!$C$5*$C9+'Scaling_Fits'!$D$5 -> -0.65381895 | E9: ='Scaling_Fits'!$C$7*$C9+'Scaling_Fits'!$D$7 -> -1.0086746 | F9: ='Scaling_Fits'!$C$8*$C9+'Scaling_Fits'!$D$8 -> -0.23467482 | G9: ='Scaling_Fits'!$C$9*$C9+'Scaling_Fits'!$D$9 -> -1.6514239 | H9: ='Scaling_Fits'!$C$10*$C9+'Scaling_Fits'!$D$10 -> -0.2111504 | I9: ='Scaling_Fits'!$C$11*$C9+'Scaling_Fits'!$D$11 -> -0.69926471 | J9: ='Scaling_Fits'!$C$12*$C9+'Scaling_Fits'!$D$12 -> -2.0310486 | K9: ='Scaling_Fits'!$C$13*$C9+'Scaling_Fits'!$D$13 -> -0.90935481 | L9: ='Scaling_Fits'!$C$14*$C9+'Scaling_Fits'!$D$14 -> -1.930928 | M9: Fe step rows are absent in S1; do not cite these as raw DFT values.
A10: Ir | B10: S1 raw step_site | C10: -0.4407 | D10: -0.5867 | E10: -0.7954 | F10: 1.099 | G10: -0.9685 | H10: 0.7265 | I10: -0.2354 | J10: -1.7381 | K10: -0.7487 | L10: -1.937 | M10: Raw S1 step-site formation energies
A11: Mo | B11: S1 raw step_site | C11: -1.8417 | D11: -0.7187 | E11: -1.5107 | F11: -0.9147 | G11: -2.088 | H11: -0.6237 | I11: -0.714 | J11: -2.1565 | K11: -0.7779 | L11: -1.9302 | M11: Raw S1 step-site formation energies
A12: Ni | B12: S1 raw step_site | C12: -0.0928 | D12: -0.3841 | E12: -0.6225 | F12: 1.4944 | G12: -0.6889 | H12: 0.8989 | I12: 0.1945 | J12: -1.5053 | K12: -0.6018 | L12: -1.6489 | M12: Raw S1 step-site formation energies
A13: Os | B13: S1 raw step_site | C13: -1.1095 | D13: -0.7121 | E13: -0.8328 | F13: 0.1851 | G13: -1.488 | H13: -0.0587 | I13: -0.7034 | J13: -2.0477 | K13: -0.8323 | L13: -2.0462 | M13: Raw S1 step-site formation energies
A14: Pd | B14: S1 raw step_site | C14: 0.5637 | D14: -0.3509 | E14: -0.3902 | F14: 4.2523 | G14: 0.0039 | H14: 1.4136 | I14: 1.0455 | J14: -0.9299 | K14: -0.1422 | L14: -1.5221 | M14: Raw S1 step-site formation energies
A15: Pt | B15: S1 raw step_site | C15: 0.5895 | D15: -0.4717 | E15: -0.4476 | F15: 2.4704 | G15: -0.0476 | H15: 1.34 | I15: 0.8868 | J15: -1.3007 | K15: -0.4052 | L15: -1.8103 | M15: Raw S1 step-site formation energies
A16: Re | B16: S1 raw step_site | C16: -1.8252 | D16: -0.8013 | E16: -1.0229 | F16: -0.7695 | G16: -1.9945 | H16: -0.3796 | I16: -1.212 | J16: -2.3639 | K16: -0.9116 | L16: -1.9839 | M16: Raw S1 step-site formation energies
A17: Rh | B17: S1 raw step_site | C17: -0.458 | D17: -0.4059 | E17: -0.6357 | F17: 0.9569 | G17: -0.7745 | H17: 0.5994 | I17: -0.0044 | J17: -1.4622 | K17: -0.628 | L17: -1.6682 | M17: Raw S1 step-site formation energies
A18: Ru | B18: S1 raw step_site | C18: -1.1333 | D18: -0.4897 | E18: -0.7234 | F18: 0.2718 | G18: -1.343 | H18: 0.0089 | I18: -0.2801 | J18: -1.7391 | K18: -0.7754 | L18: -1.8005 | M18: Raw S1 step-site formation energies
A19: W | B19: S1 raw step_site | C19: -2.161 | D19: -0.6777 | E19: -1.5111 | F19: -0.8249 | G19: -2.4101 | H19: -0.5697 | I19: -1.3387 | J19: -2.4821 | K19: -1.017 | L19: -2.1039 | M19: Raw S1 step-site formation energies

Sheet Scaling_Fits
A1: Step-site scaling / transition-state relations
A2: Linear fits across the 14 raw S1 step-site metals. Predictor is E_N. These relations generate the 1D descriptor volcano.
A4: Species / state | B4: Slope a | C4: Intercept b (eV) | D4: R² | E4: n | F4: Relation | G4: Role | H4: Comment
A5: H | B5: =SLOPE('Step_Raw14'!C5:C18,'Step_Raw14'!$B$5:$B$18) -> 0.21276674 | C5: =INTERCEPT('Step_Raw14'!C5:C18,'Step_Raw14'!$B$5:$B$18) -> -0.35762198 | D5: =RSQ('Step_Raw14'!C5:C18,'Step_Raw14'!$B$5:$B$18) -> 0.89464847 | E5: 14 | F5: E(H) = a × E_N + b | G5: thermochemistry | H5: Electronic formation-energy scaling from Dataset S1 step-site rows
A6: N | B6: =SLOPE('Step_Raw14'!B5:B18,'Step_Raw14'!$B$5:$B$18) -> 1 | C6: =INTERCEPT('Step_Raw14'!B5:B18,'Step_Raw14'!$B$5:$B$18) -> 0 | D6: =RSQ('Step_Raw14'!B5:B18,'Step_Raw14'!$B$5:$B$18) -> 1 | E6: 14 | F6: E(N) = a × E_N + b | G6: descriptor | H6: Electronic formation-energy scaling from Dataset S1 step-site rows
A7: N2 | B7: =SLOPE('Step_Raw14'!D5:D18,'Step_Raw14'!$B$5:$B$18) -> 0.24912021 | C7: =INTERCEPT('Step_Raw14'!D5:D18,'Step_Raw14'!$B$5:$B$18) -> -0.66186921 | D7: =RSQ('Step_Raw14'!D5:D18,'Step_Raw14'!$B$5:$B$18) -> 0.80938468 | E7: 14 | F7: E(N2) = a × E_N + b | G7: molecular adsorption | H7: Electronic formation-energy scaling from Dataset S1 step-site rows
A8: N-N | B8: =SLOPE('Step_Raw14'!E5:E18,'Step_Raw14'!$B$5:$B$18) -> 1.8644319 | C8: =INTERCEPT('Step_Raw14'!E5:E18,'Step_Raw14'!$B$5:$B$18) -> 2.3608392 | D8: =RSQ('Step_Raw14'!E5:E18,'Step_Raw14'!$B$5:$B$18) -> 0.96222191 | E8: 14 | F8: E(N-N) = a × E_N + b | G8: N2 dissociation TS | H8: Electronic formation-energy scaling from Dataset S1 step-site rows
A9: NH | B9: =SLOPE('Step_Raw14'!F5:F18,'Step_Raw14'!$B$5:$B$18) -> 0.7092631 | C9: =INTERCEPT('Step_Raw14'!F5:F18,'Step_Raw14'!$B$5:$B$18) -> -0.66404413 | D9: =RSQ('Step_Raw14'!F5:F18,'Step_Raw14'!$B$5:$B$18) -> 0.9833017 | E9: 14 | F9: E(NH) = a × E_N + b | G9: thermochemistry | H9: Electronic formation-energy scaling from Dataset S1 step-site rows
A10: N-H | B10: =SLOPE('Step_Raw14'!G5:G18,'Step_Raw14'!$B$5:$B$18) -> 0.91303893 | C10: =INTERCEPT('Step_Raw14'!G5:G18,'Step_Raw14'!$B$5:$B$18) -> 1.0599099 | D10: =RSQ('Step_Raw14'!G5:G18,'Step_Raw14'!$B$5:$B$18) -> 0.98039332 | E10: 14 | F10: E(N-H) = a × E_N + b | G10: N hydrogenation TS | H10: Electronic formation-energy scaling from Dataset S1 step-site rows
A11: NH-H | B11: =SLOPE('Step_Raw14'!H5:H18,'Step_Raw14'!$B$5:$B$18) -> 0.74585973 | C11: =INTERCEPT('Step_Raw14'!H5:H18,'Step_Raw14'!$B$5:$B$18) -> 0.33906201 | D11: =RSQ('Step_Raw14'!H5:H18,'Step_Raw14'!$B$5:$B$18) -> 0.97796811 | E11: 14 | F11: E(NH-H) = a × E_N + b | G11: NH hydrogenation TS | H11: Electronic formation-energy scaling from Dataset S1 step-site rows
A12: NH2 | B12: =SLOPE('Step_Raw14'!I5:I18,'Step_Raw14'!$B$5:$B$18) -> 0.40870676 | C12: =INTERCEPT('Step_Raw14'!I5:I18,'Step_Raw14'!$B$5:$B$18) -> -1.4620795 | D12: =RSQ('Step_Raw14'!I5:I18,'Step_Raw14'!$B$5:$B$18) -> 0.95543262 | E12: 14 | F12: E(NH2) = a × E_N + b | G12: thermochemistry | H12: Electronic formation-energy scaling from Dataset S1 step-site rows
A13: NH2-H | B13: =SLOPE('Step_Raw14'!J5:J18,'Step_Raw14'!$B$5:$B$18) -> 0.41136389 | C13: =INTERCEPT('Step_Raw14'!J5:J18,'Step_Raw14'!$B$5:$B$18) -> -0.33668665 | D13: =RSQ('Step_Raw14'!J5:J18,'Step_Raw14'!$B$5:$B$18) -> 0.90436965 | E13: 14 | F13: E(NH2-H) = a × E_N + b | G13: NH2 hydrogenation TS | H13: Electronic formation-energy scaling from Dataset S1 step-site rows
A14: NH3 | B14: =SLOPE('Step_Raw14'!K5:K18,'Step_Raw14'!$B$5:$B$18) -> 0.17364205 | C14: =INTERCEPT('Step_Raw14'!K5:K18,'Step_Raw14'!$B$5:$B$18) -> -1.6891973 | D14: =RSQ('Step_Raw14'!K5:K18,'Step_Raw14'!$B$5:$B$18) -> 0.86548051 | E14: 14 | F14: E(NH3) = a × E_N + b | G14: thermochemistry | H14: Electronic formation-energy scaling from Dataset S1 step-site rows

Sheet Thermo_673K
A1: Thermochemistry and MKM controls
A2: Fixed activity-volcano conditions and gas/adsorbate free-energy treatment used by the reduced numerical solver.
A4: Control | B4: Value | C4: Unit / state | D4: Used in model | E4: Source / method | F4: Equation / note
A5: Temperature | B5: 673 | C5: K | D5: Yes | E5: Wang 2021 figure condition
A6: pN2 | B6: 24.5 | C6: bar | D6: Yes | E6: Wang 2021 figure condition
A7: pH2 | B7: 74.25 | C7: bar | D7: Yes | E7: Wang 2021 figure condition
A8: pNH3 | B8: 1 | C8: bar | D8: Yes | E8: Wang 2021 figure condition
A9: H2 gas thermal correction | B9: -0.59640152 | C9: eV @ 673 K, 1 bar | D9: Yes | E9: ideal-gas statistical thermodynamics | F9: G(T,p°)-E_elec
A10: N2 gas thermal correction | B10: -1.1286367 | C10: eV @ 673 K, 1 bar | D10: Yes | E10: ideal-gas statistical thermodynamics | F10: G(T,p°)-E_elec
A11: NH3 gas thermal correction | B11: -0.39828187 | C11: eV @ 673 K, 1 bar | D11: Yes | E11: ideal-gas statistical thermodynamics | F11: G(T,p°)-E_elec
A12: NH3 ΔGf° | B12: 0.31953876 | C12: eV/NH3 @ 673 K, 1 bar | D12: Yes | E12: derived from S1 NH3 formation energy + gas thermal corrections | F12: relative to 1/2 N2 + 3/2 H2
A15: Reduced mechanism
A16: N2(g)+* ⇌ N2* | C16: Adsorption/desorption steps are treated as quasi-equilibrated. Four surface reactions use S1 TS energetics. Forward/reverse constants follow transition-state theory and detailed balance. Surface coverages satisfy a one-site balance. Vibrational corrections use harmonic free energies from S1 frequencies.
A17: N2*+* ⇌ 2N*
A18: H2(g)+2* ⇌ 2H*
A19: N*+H* ⇌ NH*+*
A20: NH*+H* ⇌ NH2*+*
A21: NH2*+H* ⇌ NH3*+*
A22: NH3* ⇌ NH3(g)+*

Sheet MKM_15
A1: 15-metal descriptor activity ranking
A2: Main result: each metal is placed by step-site E_N; all remaining states/TS follow the fitted 14-metal step scaling relations.
A4: Rank | B4: Metal | C4: E_N (eV) | D4: log10 TOF | E4: TOF (s^-1) | F4: E_N source | G4: theta_* | H4: theta_N | I4: theta_H | J4: theta_NH | K4: theta_NH2 | L4: theta_NH3 | M4: Ea N2 diss (eV) | N4: Ea N→NH (eV) | O4: Ea NH→NH2 (eV) | P4: Ea NH2→NH3 (eV)
A5: 1 | B5: Ru | C5: -1.1333 | D5: -3.4511885 | E5: 0.0003538437 | F5: S1_step_raw | G5: 8.3891799e-05 | H5: 0.61070315 | I5: 0.015604696 | J5: 0.12274647 | K5: 0.24686382 | L5: 0.0010871613 | M5: 1.3733023 | N5: 1.6660676 | O5: 1.4614821 | P5: 1.6501645
A6: 2 | B6: Os | C6: -1.1095 | D6: -3.4953204 | E6: 0.0003196536 | F6: S1_step_raw | G6: 0.00011688878 | H6: 0.55905875 | I6: 0.01992452 | J6: 0.12692614 | K6: 0.28890154 | L6: 0.0014105861 | M6: 1.4117467 | N6: 1.6589341 | O6: 1.4572892 | P6: 1.6451639
A7: 3 | B7: Fe | C7: -1.3921206 | D7: -5.3099701 | E7: 4.8981255e-06 | F7: terrace_to_step_scaling | G7: 1.9312799e-07 | H7: 0.92567476 | I7: 9.2845817e-05 | J7: 0.048861928 | K7: 0.025344473 | L7: 5.4321295e-06 | M7: 0.95522636 | N7: 1.7436433 | O7: 1.5070785 | P7: 1.7045452
A8: 4 | B8: Rh | C8: -0.458 | D8: -8.0434865 | E8: 9.047186e-09 | F8: S1_step_raw | G8: 0.021964552 | H8: 0.0013688148 | I8: 0.34300177 | J8: 0.0081891378 | K8: 0.54588883 | L8: 0.037686751 | M8: 2.4641223 | N8: 1.4636614 | O8: 1.3425144 | P8: 1.5082775
A9: 5 | B9: Ir | C9: -0.4407 | D9: -8.2025666 | E9: 6.2723951e-09 | F9: S1_step_raw | G9: 0.024151954 | H9: 0.0011169226 | I9: 0.35396639 | J9: 0.0072875576 | K9: 0.53135596 | L9: 0.039348033 | M9: 2.4920672 | N9: 1.4584761 | O9: 1.3394666 | P9: 1.5046426
A10: 6 | B10: Co | C10: -0.2701 | D10: -9.8273393 | E10: 1.4881979e-10 | F10: S1_step_raw | G10: 0.057744612 | H10: 0.00014094175 | I10: 0.4525876 | J10: 0.0021628548 | K10: 0.38177234 | L10: 0.056447812 | M10: 2.7676393 | N10: 1.4073426 | O10: 1.309412 | P10: 1.4687979
A11: 7 | B11: Re | C11: -1.8252 | D11: -10.563179 | E11: 2.7341418e-11 | F11: S1_step_raw | G11: 7.185133e-11 | H11: 0.9933872 | I11: 1.691926e-07 | J11: 0.0062635036 | K11: 0.00034907436 | L11: 7.3909933e-09 | M11: 0.2556682 | N11: 1.8734493 | O11: 1.5833742 | P11: 1.7955394
A12: 8 | B12: Mo | C12: -1.8417 | D12: -10.758861 | E12: 1.7423644e-11 | F12: S1_step_raw | G12: 5.4089319e-11 | H12: 0.99393417 | I12: 1.3531554e-07 | J12: 0.0057703796 | K12: 0.00029527063 | L12: 5.8456773e-09 | M12: 0.22901556 | N12: 1.8783948 | O12: 1.586281 | P12: 1.7990062
A13: 9 | B13: Ni | C13: -0.0928 | D13: -11.627797 | E13: 2.3561519e-12 | F13: S1_step_raw | G13: 0.12560314 | H13: 1.4414945e-05 | I13: 0.51368624 | J13: 0.00053804257 | K13: 0.23803845 | L13: 0.072208591 | M13: 3.0540341 | N13: 1.3542008 | O13: 1.2781771 | P13: 1.4315455
A14: 10 | B14: W | C14: -2.161 | D14: -14.55222 | E14: 2.8040107e-15 | F14: S1_step_raw | G14: 2.2087697e-13 | H14: 0.99881743 | I14: 1.7829134e-09 | J14: 0.0011711 | K14: 1.1465523e-05 | L14: 6.2096468e-11 | M14: 0 | N14: 1.9740979 | O14: 1.6425321 | P14: 1.8660942
A15: 11 | B15: Pd | C15: 0.5637 | D15: -19.338488 | E15: 4.5868211e-20 | F15: S1_step_raw | G15: 0.67085868 | H15: 9.3374011e-10 | I15: 0.24678621 | J15: 9.366029e-07 | K15: 0.012444755 | L15: 0.054020343 | M15: 4.1144862 | N15: 1.1574295 | O15: 1.1625214 | P15: 1.2936085
A16: 12 | B16: Pt | C16: 0.5895 | D16: -19.672212 | E16: 2.127101e-20 | F16: S1_step_raw | G16: 0.6916351 | H16: 6.1697564e-10 | I16: 0.23145123 | J16: 7.0431838e-07 | K16: 0.010697161 | L16: 0.051553123 | M16: 4.1561612 | N16: 1.1496965 | O16: 1.1579762 | P16: 1.2881877
... A19: 15 | B19: Au | C19: 3.0029 | D19: -53.047577 | E19: 8.962379e-54 | F19: S1_step_raw | G19: 0.99989734 | H19: 7.542878e-28 | I19: 4.7779884e-05 | J19: 1.5469297e-19 | K19: 6.3513733e-10 | L19: 5.4216784e-05 | M19: 8.0545544 | N19: 0.42633342 | O19: 0.73280723 | P19: 0.78110916

Sheet Direct_DFT_Check
A1: Diagnostic — direct S1 full-energetics MKM
A2: This is not the headline 1D volcano. It shows what the same reduced MKM does when every available S1 step energy is used directly; Fe remains scaling-estimated.
A4: Rank | B4: Metal | C4: E_N (eV) | D4: log10 TOF | E4: TOF (s^-1) | F4: E_N source | G4: theta_* | H4: theta_N | I4: theta_H | J4: theta_NH | K4: theta_NH2 | L4: theta_NH3 | M4: Ea N2 diss (eV) | N4: Ea N→NH (eV) | O4: Ea NH→NH2 (eV) | P4: Ea NH2→NH3 (eV)
A5: 1 | B5: Rh | C5: -0.458 | D5: -3.009025 | E5: 0.00097943353 | F5: S1 raw step energetics | G5: 0.077934168 | H5: 0.003932677 | I5: 0.74423801 | J5: 0.00060585613 | K5: 0.10052135 | L5: 0.055068721 | M5: 1.8153004 | N5: 1.3754465 | O5: 1.0363093 | P5: 1.2363357
A6: 2 | B6: Ru | C6: -1.1333 | D6: -3.1858201 | E6: 0.0006518984 | F6: S1 raw step energetics | G6: 0.00015241907 | H6: 0.94303883 | I6: 0.0050801782 | J6: 0.020349167 | K6: 0.030534646 | L6: 0.00034998707 | M6: 1.269678 | N6: 1.5757944 | O6: 1.4825216 | P6: 1.4320864
A7: 3 | B7: Os | C7: -1.1095 | D7: -4.1115965 | E7: 7.7339882e-05 | F7: S1 raw step energetics | G7: 2.8632597e-05 | H7: 0.099906652 | I7: 0.030850718 | J7: 0.25354083 | K7: 0.61325964 | L7: 0.002281271 | M7: 1.2198741 | N7: 1.6059272 | O7: 1.5005226 | P7: 1.7643096
A8: 4 | B8: Fe | C8: -1.3921206 | D8: -5.3099701 | E8: 4.8981255e-06 | F8: Fe scaling-estimated | G8: 1.9312799e-07 | H8: 0.92567476 | I8: 9.2845817e-05 | J8: 0.048861928 | K8: 0.025344473 | L8: 5.4321295e-06 | M8: 0.95522636 | N8: 1.7436433 | O8: 1.5070785 | P8: 1.7045452
A9: 5 | B9: Ir | C9: -0.4407 | D9: -6.6938566 | E9: 2.0236872e-07 | F9: S1 raw step energetics | G9: 0.0040143171 | H9: 0.00027320026 | I9: 0.67436848 | J9: 0.0037993962 | K9: 0.25952479 | L9: 0.053209485 | M9: 2.0597994 | N9: 1.682211 | O9: 1.3394319 | P9: 1.4516154
A10: 6 | B10: Ni | C10: -0.0928 | D10: -6.8412559 | E10: 1.4412658e-07 | F10: S1 raw step energetics | G10: 0.12766817 | H10: 1.7618297e-05 | I10: 0.49268711 | J10: 0.00026870011 | K10: 0.27383155 | L10: 0.088113791 | M10: 2.3547268 | N10: 1.3029863 | O10: 1.2155388 | P10: 1.2861698
A11: 7 | B11: Co | C11: -0.2701 | D11: -9.1264136 | E11: 7.4745734e-10 | F11: S1 raw step energetics | G11: 0.25595036 | H11: 0.00053913666 | I11: 0.12523357 | J11: 0.05156828 | K11: 0.45190418 | L11: 0.043786384 | M11: 2.7817434 | N11: 0.86265761 | O11: 1.1183097 | P11: 1.0116716
A12: 8 | B12: Re | C12: -1.8252 | D12: -11.463509 | E12: 3.4394696e-12 | F12: S1 raw step energetics | G12: 9.3975233e-11 | H12: 0.98579633 | I12: 4.1157312e-07 | J12: 0.0097343992 | K12: 0.0044688582 | L12: 2.6908447e-09 | M12: 0.23261934 | N12: 2.1301264 | O12: 1.4374006 | P12: 2.1151702
A13: 9 | B13: Mo | C13: -1.8417 | D13: -13.034142 | E13: 9.243954e-14 | F13: S1 raw step energetics | G13: 2.9551078e-11 | H13: 0.96483795 | I13: 3.5297021e-08 | J13: 0.03508398 | K13: 7.7325662e-05 | L13: 6.8162655e-10 | M13: 0.5642865 | N13: 1.8798475 | O13: 2.0006136 | P13: 1.9471888
A14: 10 | B14: Pt | C14: 0.5895 | D14: -15.030032 | E14: 9.3318464e-16 | F14: S1 raw step energetics | G14: 0.038037663 | H14: 3.3105845e-11 | I14: 0.8885335 | J14: 2.5951587e-09 | K14: 0.0010752245 | L14: 0.07214411 | M14: 3.121662 | N14: 1.1856262 | O14: 1.3697171 | P14: 1.2784756
A15: 11 | B15: W | C15: -2.161 | D15: -15.730329 | E15: 1.8606751e-16 | F15: S1 raw step energetics | G15: 2.2093293e-13 | H15: 0.94906622 | I15: 1.0419486e-10 | J15: 0.050840907 | K15: 9.2863638e-05 | L15: 7.9965812e-11 | M15: 0.60565865 | N15: 2.0653651 | O15: 1.6424886 | P15: 1.9800376
A16: 12 | B16: Cu | C16: 1.2491 | D16: -26.134136 | E16: 7.3428341e-27 | F16: S1 raw step energetics | G16: 0.96468278 | H16: 1.7352438e-14 | I16: 0.014557388 | J16: 3.3677528e-09 | K16: 0.0010820124 | L16: 0.0026296056 | M16: 5.0471105 | N16: 1.0433893 | O16: 1.2556535 | P16: 1.319362
... A19: 15 | B19: Au | C19: 3.0029 | D19: -57.098919 | E19: 7.9630742e-58 | F19: S1 raw step energetics | G19: 0.8573295 | H19: 1.0519563e-27 | I19: 5.6006737e-05 | J19: 4.5393316e-19 | K19: 1.9311932e-09 | L19: 0.00048578931 | M19: 9.2982205 | N19: 0.53402704 | O19: 0.78921517 | P19: 0.87145871

Sheet Volcano_1D
A1: True activity volcano — 1D descriptor model
A2: x = E_N; y = log10 TOF_NH3. Smooth curve is obtained by S1-derived scaling/BEP relations + reduced mean-field MKM.
A4: E_N grid (eV) | B4: log10 TOF | C4: TOF (s^-1) | D4: theta_* | E4: theta_N | F4: theta_H | H4: Metal | I4: Metal E_N | J4: Metal logTOF
A5: -2.6 | B5: -19.773773 | C5: 1.6835526e-20 | D5: 1.1406311e-16 | E5: 0.99987006 | F5: 4.6087999e-12 | H5: W | I5: -2.161 | J5: -14.55222
A6: -2.575 | B6: -19.476376 | C6: 3.3390573e-20 | D6: 1.7552978e-16 | E6: 0.9998527 | F6: 6.4708405e-12 | H6: Mo | I6: -1.8417 | J6: -10.758861
A7: -2.55 | B7: -19.178981 | C7: 6.6224519e-20 | D7: 2.7011915e-16 | E7: 0.99983301 | F7: 9.085159e-12 | H7: Re | I7: -1.8252 | J7: -10.563179
A8: -2.525 | B8: -18.881589 | C8: 1.313443e-19 | D8: 4.1567968e-16 | E8: 0.99981068 | F8: 1.2755669e-11 | H8: Fe | I8: -1.3921206 | J8: -5.3099701
A9: -2.5 | B9: -18.584199 | C9: 2.6049581e-19 | D9: 6.3967728e-16 | E9: 0.99978536 | F9: 1.7909053e-11 | H9: Ru | I9: -1.1333 | J9: -3.4511885
A10: -2.475 | B10: -18.286813 | C10: 5.1663873e-19 | D10: 9.8437729e-16 | E10: 0.99975665 | F10: 2.5144358e-11 | H10: Os | I10: -1.1095 | J10: -3.4953204
A11: -2.45 | B11: -17.989431 | C11: 1.0246356e-18 | D11: 1.5148184e-15 | E11: 0.9997241 | F11: 3.5302609e-11 | H11: Rh | I11: -0.458 | J11: -8.0434865
A12: -2.425 | B12: -17.692052 | C12: 2.032112e-18 | D12: 2.3310826e-15 | E12: 0.99968717 | F12: 4.956455e-11 | H12: Ir | I12: -0.4407 | J12: -8.2025666
A13: -2.4 | B13: -17.394679 | C13: 4.0301479e-18 | D13: 3.5871754e-15 | E13: 0.9996453 | F13: 6.9587843e-11 | H13: Co | I13: -0.2701 | J13: -9.8273393
A14: -2.375 | B14: -17.097311 | C14: 7.9926128e-18 | D14: 5.5200767e-15 | E14: 0.9995978 | F14: 9.769968e-11 | H14: Ni | I14: -0.0928 | J14: -11.627797
A15: -2.35 | B15: -16.79995 | C15: 1.5850765e-17 | D15: 8.4944417e-15 | E15: 0.99954392 | F15: 1.3716716e-10 | H15: Pd | I15: 0.5637 | J15: -19.338488
A16: -2.325 | B16: -16.502596 | C16: 3.143435e-17 | D16: 1.3071379e-14 | E16: 0.9994828 | F16: 1.9257681e-10 | H16: Pt | I16: 0.5895 | J16: -19.672212
... A19: -2.25 | B19: -15.610587 | C19: 2.4513925e-16 | D19: 4.762749e-14 | E19: 0.99924543 | F19: 5.328955e-10 | H19: Au | I19: 3.0029 | J19: -53.047577
A20: -2.225 | B20: -15.313274 | C20: 4.8610081e-16 | D20: 7.328697e-14 | E20: 0.99914405 | F20: 7.4813228e-10
A21: -2.2 | B21: -15.015974 | C21: 9.6388614e-16 | D21: 1.1276904e-13 | E21: 0.99902894 | F21: 1.0502889e-09
A22: -2.175 | B22: -14.718691 | C22: 1.9112125e-15 | D22: 1.7351867e-13 | E22: 0.99889823 | F22: 1.4744578e-09 | H22: 1D optimum E_N (eV) | I22: -1.175
A23: -2.15 | B23: -14.421426 | C23: 3.7894283e-15 | D23: 2.6698988e-13 | E23: 0.99874977 | F23: 2.0698945e-09 | H23: Peak log10 TOF | I23: -3.4140997
A24: -2.125 | B24: -14.124183 | C24: 7.5130652e-15 | D24: 4.1080393e-13 | E24: 0.99858109 | F24: 2.9057301e-09 | H24: Peak TOF (s^-1) | I24: 0.00038538989
A25: -2.1 | B25: -13.826964 | C25: 1.4894852e-14 | D25: 6.320688e-13 | E25: 0.99838939 | F25: 4.0789869e-09
A26: -2.075 | B26: -13.529773 | C26: 2.9527533e-14 | D26: 9.7248449e-13 | E26: 0.99817144 | F26: 5.7258228e-09
A27: -2.05 | B27: -13.232614 | C27: 5.8530977e-14 | D27: 1.4961942e-12 | E27: 0.99792356 | F27: 8.0373051e-09
A28: -2.025 | B28: -12.935493 | C28: 1.1601312e-13 | D28: 2.3018571e-12 | E28: 0.99764151 | F28: 1.1281533e-08
A29: -2 | B29: -12.638415 | C29: 2.2992457e-13 | D29: 3.5412102e-12 | E29: 0.99732042 | F29: 1.5834659e-08
A30: -1.975 | B30: -12.341386 | C30: 4.5563167e-13 | D30: 5.4476047e-12 | E30: 0.9969547 | F30: 2.2224391e-08
A31: -1.95 | B31: -12.044415 | C31: 9.0278609e-13 | D31: 8.379869e-12 | E31: 0.99653787 | F31: 3.1190963e-08
A32: -1.925 | B32: -11.747511 | C32: 1.7885003e-12 | D32: 1.2889716e-11 | E32: 0.99606248 | F32: 4.3772583e-08
A33: -1.9 | B33: -11.450684 | C33: 3.542547e-12 | D33: 1.9825321e-11 | E33: 0.99551988 | F33: 6.1425162e-08
A34: -1.875 | B34: -11.153948 | C34: 7.0153936e-12 | D34: 3.0490431e-11 | E34: 0.99490006 | F34: 8.6190007e-08
A35: -1.85 | B35: -10.857317 | C35: 1.38894e-11 | D35: 4.6888733e-11 | E35: 0.99419137 | F35: 1.2092862e-07
A36: -1.825 | B36: -10.560807 | C36: 2.7491128e-11 | D36: 7.2099045e-11 | E36: 0.99338026 | F36: 1.6965138e-07
... A245: 3.4 | B245: -58.591761 | C245: 2.5599938e-59 | D245: 0.99997223 | E245: 8.0144888e-31 | F245: 1.1132033e-05

Sheet Sources
A1: Sources and model provenance
A2: Plain URLs are included for reuse outside ChatGPT. No data-rating system is used.
A4: Item | B4: URL / file | C4: Used for | D4: Specific note | E4: Access / model status
A5: Wang & Abild-Pedersen, PNAS 2021 | B5: https://doi.org/10.1073/pnas.2106527118 | C5: DFT energetics / activity-map context | D5: Theory-aided discovery of high-temperature ammonia synthesis catalysts | E5: Primary article
A6: PMC full text | B6: https://pmc.ncbi.nlm.nih.gov/articles/PMC8325328/ | C6: Methods / conditions / supplementary link | D6: 673 K; 24.5 bar N2; 74.25 bar H2; 1 bar NH3; CatMAP in source paper | E6: Primary full text
A7: Dataset S1 | B7: pnas.2106527118.sd01.txt | C7: 444 parsed formation-energy/frequency rows | D7: Uploaded supplementary file used directly in this workbook | E7: User-uploaded primary supplementary
A8: MKM reconstruction | B8: mkm_s1_activity_v2.py | C8: Reduced one-site mean-field solver | D8: TST, detailed balance, harmonic adsorbate/TS vibrations, ideal-gas gases | E8: This workbook model; not exact source CatMAP
